Workbook

Sheet Sheet1
A1: district_id | B1: district_name | C1: gender | D1: age_group | E1: population | F1: district
A2: 1703202 | B2: Oltinko‘l tumani | C2: Аёл | D2: 18-29 | E2: 15935 | F2: =+VLOOKUP(A2,Лист1!$B$2:$E$207,3,FALSE) -> Олтинкўл
A3: 1703202 | B3: Oltinko‘l tumani | C3: Аёл | D3: 30-49 | E3: 26857 | F3: =+VLOOKUP(A3,Лист1!$B$2:$E$207,3,FALSE) -> Олтинкўл
A4: 1703202 | B4: Oltinko‘l tumani | C4: Аёл | D4: 50-65 | E4: 13162 | F4: =+VLOOKUP(A4,Лист1!$B$2:$E$207,3,FALSE) -> Олтинкўл
A5: 1703202 | B5: Oltinko‘l tumani | C5: Аёл | D5: Over 65 | E5: 5320 | F5: =+VLOOKUP(A5,Лист1!$B$2:$E$207,3,FALSE) -> Олтинкўл
A6: 1703202 | B6: Oltinko‘l tumani | C6: Эркак | D6: 18-29 | E6: 16783 | F6: =+VLOOKUP(A6,Лист1!$B$2:$E$207,3,FALSE) -> Олтинкўл
A7: 1703202 | B7: Oltinko‘l tumani | C7: Эркак | D7: 30-49 | E7: 26823 | F7: =+VLOOKUP(A7,Лист1!$B$2:$E$207,3,FALSE) -> Олтинкўл
A8: 1703202 | B8: Oltinko‘l tumani | C8: Эркак | D8: 50-65 | E8: 12237 | F8: =+VLOOKUP(A8,Лист1!$B$2:$E$207,3,FALSE) -> Олтинкўл
A9: 1703202 | B9: Oltinko‘l tumani | C9: Эркак | D9: Over 65 | E9: 4040 | F9: =+VLOOKUP(A9,Лист1!$B$2:$E$207,3,FALSE) -> Олтинкўл
A10: 1703203 | B10: Andijon tumani | C10: Аёл | D10: 18-29 | E10: 24247 | F10: =+VLOOKUP(A10,Лист1!$B$2:$E$207,3,FALSE) -> Андижон
A11: 1703203 | B11: Andijon tumani | C11: Аёл | D11: 30-49 | E11: 39603 | F11: =+VLOOKUP(A11,Лист1!$B$2:$E$207,3,FALSE) -> Андижон
A12: 1703203 | B12: Andijon tumani | C12: Аёл | D12: 50-65 | E12: 20544 | F12: =+VLOOKUP(A12,Лист1!$B$2:$E$207,3,FALSE) -> Андижон
A13: 1703203 | B13: Andijon tumani | C13: Аёл | D13: Over 65 | E13: 8791 | F13: =+VLOOKUP(A13,Лист1!$B$2:$E$207,3,FALSE) -> Андижон
... A1649: 1735401 | B1649: Nukus shahri | C1649: Эркак | D1649: Over 65 | E1649: 7217 | F1649: =+VLOOKUP(A1649,Лист1!$B$2:$E$207,3,FALSE) -> Нукус ш.

Sheet Лист1
A1: ADM2_PCODE | B1: Code | C1: district_latin | D1: district_kirill | E1: ADM2_UZ
A2: UZ35204 | B2: 1735204 | C2: Amudaryo | D2: Амударё | E2: Amudaryo
A3: UZ22202 | B3: 1722202 | C3: Angor | D3: Ангор | E3: Angor
A4: UZ27407 | B4: 1727407 | C4: Angren shahri | D4: Ангрен ш. | E4: Angren sh.
A5: UZ03203 | B5: 1703203 | C5: Andijon | D5: Андижон | E5: Andijon
A6: UZ03401 | B6: 1703401 | C6: Andijon shahri | D6: Андижон ш. | E6: Andijon sh.
A7: UZ08201 | B7: 1708201 | C7: Arnasoy | D7: Арнасой | E7: Arnasoy
A8: UZ03224 | B8: 1703224 | C8: Asaka | D8: Асака | E8: Asaka
A9: UZ03206 | B9: 1703206 | C9: Baliqchi | D9: Балиқчи | E9: Baliqchi
B10: 1722203 | C10: Bandixon | D10: Бандихон | E10: Bandixon
A11: UZ08204 | B11: 1708204 | C11: Baxmal | D11: Бахмал | E11: Baxmal
A12: UZ27220 | B12: 1727220 | C12: Bekobod | D12: Бекобод | E12: Bekobod
A13: UZ27413 | B13: 1727413 | C13: Bekobod shahri | D13: Бекобод ш. | E13: Bekobod sh.
A14: UZ26264 | B14: 1726264 | C14: Bektemir | D14: Бектемир | E14: Bektemir
A15: UZ35207 | B15: 1735207 | C15: Beruniy | D15: Беруний | E15: Beruniy
A16: UZ30215 | B16: 1730215 | C16: Beshariq | D16: Бешариқ | E16: Beshariq
A17: UZ30209 | B17: 1730209 | C17: Bog‘dod | D17: Боғдод | E17: Bog'dod
A18: UZ33204 | B18: 1733204 | C18: Bog‘ot | D18: Боғот | E18: Bog'ot
A19: UZ24212 | B19: 1724212 | C19: Boyovut | D19: Боёвут | E19: Boyovut
A20: UZ22204 | B20: 1722204 | C20: Boysun | D20: Бойсун | E20: Boysun
A21: UZ30212 | B21: 1730212 | C21: Buvayda | D21: Бувайда | E21: Buvayda
A22: UZ03209 | B22: 1703209 | C22: Bo‘ston | D22: Бўстон | E22: Bo'z
B23: 1735209 | C23: Bo‘zatov | D23: Бўзатов | E23: Bo‘zatov
A24: UZ27228 | B24: 1727228 | C24: Bo‘ka | D24: Бўка | E24: Bo'ka
A25: UZ03210 | B25: 1703210 | C25: Buloqboshi | D25: Булоқбоши | E25: Buloqboshi
A26: UZ18206 | B26: 1718206 | C26: Bulung‘ur | D26: Булунғур | E26: Bulung'ur
A27: UZ27224 | B27: 1727224 | C27: Bo‘stonliq | D27: Бўстонлиқ | E27: Bo'stonliq
A28: UZ06207 | B28: 1706207 | C28: Buxoro | D28: Бухоро тумани | E28: Buxoro
A29: UZ06401 | B29: 1706401 | C29: Buxoro shahri | D29: Бухоро ш. | E29: Buxoro sh.
A30: UZ06212 | B30: 1706212 | C30: Vobkent | D30: Вобкент | E30: Vobkent
A31: UZ08209 | B31: 1708209 | C31: G‘allaorol | D31: Ғаллаорол | E31: G'allaorol
A32: UZ06215 | B32: 1706215 | C32: G‘ijduvon | D32: Ғиждувон | E32: G'ijduvon
A33: UZ10207 | B33: 1710207 | C33: G‘uzor | D33: Ғузор | E33: G'uzor
A34: UZ24220 | B34: 1724220 | C34: Guliston | D34: Гулистон | E34: Guliston
A35: UZ24401 | B35: 1724401 | C35: Guliston shahri | D35: Гулистон ш. | E35: Guliston sh.
... A139: UZ18238 | B139: 1718238 | C139: Tayloq | D139: Тойлоқ | E139: Tayloq
B140: 1735228 | C140: Taxiatosh | D140: Тахиатош | E140: Taxiatosh
A141: UZ35230 | B141: 1735230 | C141: Taxtako‘pir | D141: Тахтакўпир | E141: Taxtako'pir
A142: UZ22220 | B142: 1722220 | C142: Termiz | D142: Термиз | E142: Termiz
A143: UZ22401 | B143: 1722401 | C143: Termiz shahri | D143: Термиз ш. | E143: Termiz sh.
...
