Workbook

Sheet bs
B3: 2025 йил май | E3: 2025 йил август
A4: district | B4: Умумий индекс | C4: Жорий ҳолат | D4: Кутилмалар | E4: Умумий индекс | F4: Жорий ҳолат | G4: Кутилмалар
A5: Самарканд вилояти | B5: 119 | C5: 97 | D5: 141 | E5: =+VLOOKUP(A5,'bs (черн)'!A:D,2,0) -> 122 | F5: =+VLOOKUP(A5,'bs (черн)'!A:D,3,0) -> 108 | G5: =+VLOOKUP(A5,'bs (черн)'!A:D,4,0) -> 136 | H5: =+F5-C5 -> 11
A6: Коракалпокистон Республикаси | B6: 116 | C6: 93 | D6: 139 | E6: =+VLOOKUP(A6,'bs (черн)'!A:D,2,0) -> 116 | F6: =+VLOOKUP(A6,'bs (черн)'!A:D,3,0) -> 103 | G6: =+VLOOKUP(A6,'bs (черн)'!A:D,4,0) -> 129 | H6: =+F6-C6 -> 10
A7: Хоразм вилояти | B7: 116 | C7: 95 | D7: 138 | E7: =+VLOOKUP(A7,'bs (черн)'!A:D,2,0) -> 119 | F7: =+VLOOKUP(A7,'bs (черн)'!A:D,3,0) -> 105 | G7: =+VLOOKUP(A7,'bs (черн)'!A:D,4,0) -> 134 | H7: =+F7-C7 -> 10
A8: Бухоро вилояти | B8: 115 | C8: 95 | D8: 134 | E8: =+VLOOKUP(A8,'bs (черн)'!A:D,2,0) -> 121 | F8: =+VLOOKUP(A8,'bs (черн)'!A:D,3,0) -> 105 | G8: =+VLOOKUP(A8,'bs (черн)'!A:D,4,0) -> 138 | H8: =+F8-C8 -> 10
A9: Наманган вилояти | B9: 121 | C9: 98 | D9: 145 | E9: =+VLOOKUP(A9,'bs (черн)'!A:D,2,0) -> 123 | F9: =+VLOOKUP(A9,'bs (черн)'!A:D,3,0) -> 107 | G9: =+VLOOKUP(A9,'bs (черн)'!A:D,4,0) -> 140 | H9: =+F9-C9 -> 9
A10: Навоий вилояти | B10: 119 | C10: 98 | D10: 139 | E10: =+VLOOKUP(A10,'bs (черн)'!A:D,2,0) -> 119 | F10: =+VLOOKUP(A10,'bs (черн)'!A:D,3,0) -> 106 | G10: =+VLOOKUP(A10,'bs (черн)'!A:D,4,0) -> 133 | H10: =+F10-C10 -> 8
A11: Сирдарё вилояти | B11: 115 | C11: 94 | D11: 137 | E11: =+VLOOKUP(A11,'bs (черн)'!A:D,2,0) -> 118 | F11: =+VLOOKUP(A11,'bs (черн)'!A:D,3,0) -> 102 | G11: =+VLOOKUP(A11,'bs (черн)'!A:D,4,0) -> 133 | H11: =+F11-C11 -> 8
A12: Жиззах вилояти | B12: 119 | C12: 97 | D12: 142 | E12: =+VLOOKUP(A12,'bs (черн)'!A:D,2,0) -> 121 | F12: =+VLOOKUP(A12,'bs (черн)'!A:D,3,0) -> 104 | G12: =+VLOOKUP(A12,'bs (черн)'!A:D,4,0) -> 138 | H12: =+F12-C12 -> 7
A13: Фаргона вилояти | B13: 117 | C13: 95 | D13: 139 | E13: =+VLOOKUP(A13,'bs (черн)'!A:D,2,0) -> 117 | F13: =+VLOOKUP(A13,'bs (черн)'!A:D,3,0) -> 102 | G13: =+VLOOKUP(A13,'bs (черн)'!A:D,4,0) -> 132 | H13: =+F13-C13 -> 7
A14: Сурхандарё вилояти | B14: 115 | C14: 95 | D14: 134 | E14: =+VLOOKUP(A14,'bs (черн)'!A:D,2,0) -> 118 | F14: =+VLOOKUP(A14,'bs (черн)'!A:D,3,0) -> 102 | G14: =+VLOOKUP(A14,'bs (черн)'!A:D,4,0) -> 134 | H14: =+F14-C14 -> 7
A15: Тошкент шахри | B15: 114 | C15: 95 | D15: 133 | E15: =+VLOOKUP(A15,'bs (черн)'!A:D,2,0) -> 119 | F15: =+VLOOKUP(A15,'bs (черн)'!A:D,3,0) -> 102 | G15: =+VLOOKUP(A15,'bs (черн)'!A:D,4,0) -> 135 | H15: =+F15-C15 -> 7
A16: Тошкент вилояти | B16: 113 | C16: 95 | D16: 131 | E16: =+VLOOKUP(A16,'bs (черн)'!A:D,2,0) -> 116 | F16: =+VLOOKUP(A16,'bs (черн)'!A:D,3,0) -> 101 | G16: =+VLOOKUP(A16,'bs (черн)'!A:D,4,0) -> 131 | H16: =+F16-C16 -> 6
... A18: Кашкадарё вилояти | B18: 115 | C18: 95 | D18: 136 | E18: =+VLOOKUP(A18,'bs (черн)'!A:D,2,0) -> 114 | F18: =+VLOOKUP(A18,'bs (черн)'!A:D,3,0) -> 96 | G18: =+VLOOKUP(A18,'bs (черн)'!A:D,4,0) -> 131 | H18: =+F18-C18 -> 1
A19: Республика бўйича | B19: 117 | C19: 96 | D19: 138 | E19: =+VLOOKUP(A19,'bs (черн)'!A:D,2,0) -> 119 | F19: =+VLOOKUP(A19,'bs (черн)'!A:D,3,0) -> 103 | G19: =+VLOOKUP(A19,'bs (черн)'!A:D,4,0) -> 134

Sheet bs (черн)
B1: Август
A2: Наманган вилояти | B2: 123 | C2: 107 | D2: 140
A3: Самарканд вилояти | B3: 122 | C3: 108 | D3: 136
A4: Бухоро вилояти | B4: 121 | C4: 105 | D4: 138
A5: Жиззах вилояти | B5: 121 | C5: 104 | D5: 138
A6: Андижон вилояти | B6: 119 | C6: 104 | D6: 134
A7: Навоий вилояти | B7: 119 | C7: 106 | D7: 133
A8: Тошкент шахри | B8: 119 | C8: 102 | D8: 135
A9: Хоразм вилояти | B9: 119 | C9: 105 | D9: 134
A10: Сирдарё вилояти | B10: 118 | C10: 102 | D10: 133
A11: Сурхандарё вилояти | B11: 118 | C11: 102 | D11: 134
A12: Фаргона вилояти | B12: 117 | C12: 102 | D12: 132
A13: Коракалпокистон Республикаси | B13: 116 | C13: 103 | D13: 129
... A16: Республика бўйича | B16: 119 | C16: 103 | D16: 134

Sheet bs district
B3: 2025 йил май | E3: 2025 йил август
A4: district | B4: Умумий индекс | C4: Жорий ҳолат | D4: Кутилмалар | E4: Умумий индекс | F4: Жорий ҳолат | G4: Кутилмалар
A5: Бўзатов | B5: 96 | C5: 58 | D5: 134 | E5: =+VLOOKUP(A5,'bs district (черн)'!A:D,2,0) -> 130 | F5: =+VLOOKUP(A5,'bs district (черн)'!A:D,3,0) -> 105 | G5: =+VLOOKUP(A5,'bs district (черн)'!A:D,4,0) -> 154 | H5: =+F5-C5 -> 47
A6: Қонликўл | B6: 113 | C6: 85 | D6: 141 | E6: =+VLOOKUP(A6,'bs district (черн)'!A:D,2,0) -> 123 | F6: =+VLOOKUP(A6,'bs district (черн)'!A:D,3,0) -> 121 | G6: =+VLOOKUP(A6,'bs district (черн)'!A:D,4,0) -> 124 | H6: =+F6-C6 -> 36
A7: Хонобод ш. | B7: 106 | C7: 81 | D7: 131 | E7: =+VLOOKUP(A7,'bs district (черн)'!A:D,2,0) -> 125 | F7: =+VLOOKUP(A7,'bs district (черн)'!A:D,3,0) -> 116 | G7: =+VLOOKUP(A7,'bs district (черн)'!A:D,4,0) -> 134 | H7: =+F7-C7 -> 35
A8: Бахмал | B8: 114 | C8: 90 | D8: 137 | E8: =+VLOOKUP(A8,'bs district (черн)'!A:D,2,0) -> 132 | F8: =+VLOOKUP(A8,'bs district (черн)'!A:D,3,0) -> 116 | G8: =+VLOOKUP(A8,'bs district (черн)'!A:D,4,0) -> 149 | H8: =+F8-C8 -> 26
A9: Конимех | B9: 119 | C9: 94 | D9: 144 | E9: =+VLOOKUP(A9,'bs district (черн)'!A:D,2,0) -> 128 | F9: =+VLOOKUP(A9,'bs district (черн)'!A:D,3,0) -> 119 | G9: =+VLOOKUP(A9,'bs district (черн)'!A:D,4,0) -> 138 | H9: =+F9-C9 -> 25
A10: Ғиждувон | B10: 114 | C10: 88 | D10: 140 | E10: =+VLOOKUP(A10,'bs district (черн)'!A:D,2,0) -> 128 | F10: =+VLOOKUP(A10,'bs district (черн)'!A:D,3,0) -> 112 | G10: =+VLOOKUP(A10,'bs district (черн)'!A:D,4,0) -> 143 | H10: =+F10-C10 -> 24
A11: Тойлоқ | B11: 115 | C11: 94 | D11: 135 | E11: =+VLOOKUP(A11,'bs district (черн)'!A:D,2,0) -> 125 | F11: =+VLOOKUP(A11,'bs district (черн)'!A:D,3,0) -> 117 | G11: =+VLOOKUP(A11,'bs district (черн)'!A:D,4,0) -> 133 | H11: =+F11-C11 -> 23
A12: Амударё | B12: 108 | C12: 91 | D12: 125 | E12: =+VLOOKUP(A12,'bs district (черн)'!A:D,2,0) -> 120 | F12: =+VLOOKUP(A12,'bs district (черн)'!A:D,3,0) -> 114 | G12: =+VLOOKUP(A12,'bs district (черн)'!A:D,4,0) -> 125 | H12: =+F12-C12 -> 23
A13: Ширин ш. | B13: 105 | C13: 80 | D13: 130 | E13: =+VLOOKUP(A13,'bs district (черн)'!A:D,2,0) -> 112 | F13: =+VLOOKUP(A13,'bs district (черн)'!A:D,3,0) -> 103 | G13: =+VLOOKUP(A13,'bs district (черн)'!A:D,4,0) -> 120 | H13: =+F13-C13 -> 23
A14: Бўстон | B14: 121 | C14: 100 | D14: 143 | E14: =+VLOOKUP(A14,'bs district (черн)'!A:D,2,0) -> 125 | F14: =+VLOOKUP(A14,'bs district (черн)'!A:D,3,0) -> 122 | G14: =+VLOOKUP(A14,'bs district (черн)'!A:D,4,0) -> 127 | H14: =+F14-C14 -> 22
A15: Тупроққальа | B15: 116 | C15: 89 | D15: 143 | E15: =+VLOOKUP(A15,'bs district (черн)'!A:D,2,0) -> 125 | F15: =+VLOOKUP(A15,'bs district (черн)'!A:D,3,0) -> 111 | G15: =+VLOOKUP(A15,'bs district (черн)'!A:D,4,0) -> 139 | H15: =+F15-C15 -> 22
A16: Қўштепа | B16: 112 | C16: 90 | D16: 134 | E16: =+VLOOKUP(A16,'bs district (черн)'!A:D,2,0) -> 120 | F16: =+VLOOKUP(A16,'bs district (черн)'!A:D,3,0) -> 112 | G16: =+VLOOKUP(A16,'bs district (черн)'!A:D,4,0) -> 128 | H16: =+F16-C16 -> 22
... A209: Учтепа | B209: 123 | C209: 104 | D209: 141 | E209: =+VLOOKUP(A209,'bs district (черн)'!A:D,2,0) -> 109 | F209: =+VLOOKUP(A209,'bs district (черн)'!A:D,3,0) -> 81 | G209: =+VLOOKUP(A209,'bs district (черн)'!A:D,4,0) -> 136 | H209: =+F209-C209 -> -23

Sheet bs district (черн)
B1: Август
A2: Томди | B2: 146 | C2: 141 | D2: 152
A3: Янгиер ш. | B3: 133 | C3: 107 | D3: 159
A4: Бахмал | B4: 132 | C4: 116 | D4: 149
A5: Зарафшон ш. | B5: 132 | C5: 119 | D5: 145
A6: Мингбулоқ | B6: 132 | C6: 120 | D6: 144
A7: Сариосиё | B7: 132 | C7: 118 | D7: 147
A8: Термиз | B8: 131 | C8: 110 | D8: 152
A9: Тўрақўрғон | B9: 131 | C9: 121 | D9: 142
A10: Ургут | B10: 131 | C10: 119 | D10: 142
A11: Бўзатов | B11: 130 | C11: 105 | D11: 154
A12: Учқудуқ | B12: 130 | C12: 117 | D12: 143
A13: Бектемир | B13: 129 | C13: 121 | D13: 137
... A206: Мирзачўл | B206: 104 | C206: 87 | D206: 122

Sheet q_2
B3: 2025 йил май | E3: 2025 йил август
A4: district | B4: Пасайди | C4: Ўзгармади | D4: Ошди | E4: Пасайди | F4: Ўзгармади | G4: Ошди
A5: Сирдарё вилояти | B5: 22 | C5: 59 | D5: 19 | E5: =+VLOOKUP(A5,'q_2 (черн)'!A:D,2,0) -> 18 | F5: =+VLOOKUP(A5,'q_2 (черн)'!A:D,3,0) -> 50 | G5: =+VLOOKUP(A5,'q_2 (черн)'!A:D,4,0) -> 31 | H5: =+G5-D5 -> 12
A6: Коракалпокистон Республикаси | B6: 18 | C6: 63 | D6: 18 | E6: =+VLOOKUP(A6,'q_2 (черн)'!A:D,2,0) -> 17 | F6: =+VLOOKUP(A6,'q_2 (черн)'!A:D,3,0) -> 54 | G6: =+VLOOKUP(A6,'q_2 (черн)'!A:D,4,0) -> 29 | H6: =+G6-D6 -> 11
A7: Хоразм вилояти | B7: 19 | C7: 57 | D7: 24 | E7: =+VLOOKUP(A7,'q_2 (черн)'!A:D,2,0) -> 18 | F7: =+VLOOKUP(A7,'q_2 (черн)'!A:D,3,0) -> 50 | G7: =+VLOOKUP(A7,'q_2 (черн)'!A:D,4,0) -> 32 | H7: =+G7-D7 -> 8
A8: Самарканд вилояти | B8: 17 | C8: 59 | D8: 24 | E8: =+VLOOKUP(A8,'q_2 (черн)'!A:D,2,0) -> 17 | F8: =+VLOOKUP(A8,'q_2 (черн)'!A:D,3,0) -> 50 | G8: =+VLOOKUP(A8,'q_2 (черн)'!A:D,4,0) -> 32 | H8: =+G8-D8 -> 8
A9: Наманган вилояти | B9: 19 | C9: 57 | D9: 24 | E9: =+VLOOKUP(A9,'q_2 (черн)'!A:D,2,0) -> 19 | F9: =+VLOOKUP(A9,'q_2 (черн)'!A:D,3,0) -> 48 | G9: =+VLOOKUP(A9,'q_2 (черн)'!A:D,4,0) -> 32 | H9: =+G9-D9 -> 8
A10: Бухоро вилояти | B10: 21 | C10: 59 | D10: 21 | E10: =+VLOOKUP(A10,'q_2 (черн)'!A:D,2,0) -> 19 | F10: =+VLOOKUP(A10,'q_2 (черн)'!A:D,3,0) -> 52 | G10: =+VLOOKUP(A10,'q_2 (черн)'!A:D,4,0) -> 29 | H10: =+G10-D10 -> 8
A11: Сурхандарё вилояти | B11: 20 | C11: 59 | D11: 21 | E11: =+VLOOKUP(A11,'q_2 (черн)'!A:D,2,0) -> 19 | F11: =+VLOOKUP(A11,'q_2 (черн)'!A:D,3,0) -> 52 | G11: =+VLOOKUP(A11,'q_2 (черн)'!A:D,4,0) -> 29 | H11: =+G11-D11 -> 8
A12: Навоий вилояти | B12: 17 | C12: 58 | D12: 24 | E12: =+VLOOKUP(A12,'q_2 (черн)'!A:D,2,0) -> 22 | F12: =+VLOOKUP(A12,'q_2 (черн)'!A:D,3,0) -> 47 | G12: =+VLOOKUP(A12,'q_2 (черн)'!A:D,4,0) -> 31 | H12: =+G12-D12 -> 7
A13: Фаргона вилояти | B13: 20 | C13: 55 | D13: 26 | E13: =+VLOOKUP(A13,'q_2 (черн)'!A:D,2,0) -> 19 | F13: =+VLOOKUP(A13,'q_2 (черн)'!A:D,3,0) -> 50 | G13: =+VLOOKUP(A13,'q_2 (черн)'!A:D,4,0) -> 31 | H13: =+G13-D13 -> 5
A14: Андижон вилояти | B14: 19 | C14: 56 | D14: 25 | E14: =+VLOOKUP(A14,'q_2 (черн)'!A:D,2,0) -> 18 | F14: =+VLOOKUP(A14,'q_2 (черн)'!A:D,3,0) -> 52 | G14: =+VLOOKUP(A14,'q_2 (черн)'!A:D,4,0) -> 30 | H14: =+G14-D14 -> 5
A15: Кашкадарё вилояти | B15: 19 | C15: 62 | D15: 19 | E15: =+VLOOKUP(A15,'q_2 (черн)'!A:D,2,0) -> 19 | F15: =+VLOOKUP(A15,'q_2 (черн)'!A:D,3,0) -> 56 | G15: =+VLOOKUP(A15,'q_2 (черн)'!A:D,4,0) -> 24 | H15: =+G15-D15 -> 5
A16: Жиззах вилояти | B16: 17 | C16: 58 | D16: 24 | E16: =+VLOOKUP(A16,'q_2 (черн)'!A:D,2,0) -> 16 | F16: =+VLOOKUP(A16,'q_2 (черн)'!A:D,3,0) -> 56 | G16: =+VLOOKUP(A16,'q_2 (черн)'!A:D,4,0) -> 28 | H16: =+G16-D16 -> 4
... A18: Тошкент шахри | B18: 21 | C18: 58 | D18: 21 | E18: =+VLOOKUP(A18,'q_2 (черн)'!A:D,2,0) -> 18 | F18: =+VLOOKUP(A18,'q_2 (черн)'!A:D,3,0) -> 59 | G18: =+VLOOKUP(A18,'q_2 (черн)'!A:D,4,0) -> 23 | H18: =+G18-D18 -> 2
A19: Республика бўйича ўртача | B19: 19 | C19: 58 | D19: 23 | E19: =+VLOOKUP(A19,'q_2 (черн)'!A:D,2,0) -> 18 | F19: =+VLOOKUP(A19,'q_2 (черн)'!A:D,3,0) -> 52 | G19: =+VLOOKUP(A19,'q_2 (черн)'!A:D,4,0) -> 29

Sheet q_2 (черн)
B1: Август
A2: Андижон вилояти | B2: 18 | C2: 52 | D2: 30
A3: Бухоро вилояти | B3: 19 | C3: 52 | D3: 29
A4: Жиззах вилояти | B4: 16 | C4: 56 | D4: 28
A5: Кашкадарё вилояти | B5: 19 | C5: 56 | D5: 24
A6: Коракалпокистон Республикаси | B6: 17 | C6: 54 | D6: 29
A7: Навоий вилояти | B7: 22 | C7: 47 | D7: 31
A8: Наманган вилояти | B8: 19 | C8: 48 | D8: 32
A9: Самарканд вилояти | B9: 17 | C9: 50 | D9: 32
A10: Сирдарё вилояти | B10: 18 | C10: 50 | D10: 31
A11: Сурхандарё вилояти | B11: 19 | C11: 52 | D11: 29
A12: Тошкент вилояти | B12: 20 | C12: 55 | D12: 25
A13: Тошкент шахри | B13: 18 | C13: 59 | D13: 23
... A16: Республика бўйича ўртача | B16: 18 | C16: 52 | D16: 29

Sheet q_2 district
B3: 2025 йил май | E3: 2025 йил август
A4: district | B4: Пасайди | C4: Ўзгармади | D4: Ошди | E4: Пасайди | F4: Ўзгармади | G4: Ошди
A5: Бўзатов | B5: 37 | C5: 51 | D5: 12 | E5: =+VLOOKUP(A5,'q_2 district (черн)'!A:D,2,0) -> 0 | F5: =+VLOOKUP(A5,'q_2 district (черн)'!A:D,3,0) -> 42 | G5: =+VLOOKUP(A5,'q_2 district (черн)'!A:D,4,0) -> 58 | H5: =+G5-D5 -> 46
A6: Қонликўл | B6: 26 | C6: 60 | D6: 14 | E6: =+VLOOKUP(A6,'q_2 district (черн)'!A:D,2,0) -> 11 | F6: =+VLOOKUP(A6,'q_2 district (черн)'!A:D,3,0) -> 37 | G6: =+VLOOKUP(A6,'q_2 district (черн)'!A:D,4,0) -> 51 | H6: =+G6-D6 -> 37
A7: Тупроққальа | B7: 22 | C7: 63 | D7: 15 | E7: =+VLOOKUP(A7,'q_2 district (черн)'!A:D,2,0) -> 15 | F7: =+VLOOKUP(A7,'q_2 district (черн)'!A:D,3,0) -> 44 | G7: =+VLOOKUP(A7,'q_2 district (черн)'!A:D,4,0) -> 41 | H7: =+G7-D7 -> 26
A8: Мингбулоқ | B8: 29 | C8: 49 | D8: 21 | E8: =+VLOOKUP(A8,'q_2 district (черн)'!A:D,2,0) -> 12 | F8: =+VLOOKUP(A8,'q_2 district (черн)'!A:D,3,0) -> 42 | G8: =+VLOOKUP(A8,'q_2 district (черн)'!A:D,4,0) -> 46 | H8: =+G8-D8 -> 25
A9: Сирдарё | B9: 29 | C9: 57 | D9: 14 | E9: =+VLOOKUP(A9,'q_2 district (черн)'!A:D,2,0) -> 21 | F9: =+VLOOKUP(A9,'q_2 district (черн)'!A:D,3,0) -> 40 | G9: =+VLOOKUP(A9,'q_2 district (черн)'!A:D,4,0) -> 39 | H9: =+G9-D9 -> 25
A10: Шофиркон | B10: 13 | C10: 73 | D10: 14 | E10: =+VLOOKUP(A10,'q_2 district (черн)'!A:D,2,0) -> 21 | F10: =+VLOOKUP(A10,'q_2 district (черн)'!A:D,3,0) -> 41 | G10: =+VLOOKUP(A10,'q_2 district (черн)'!A:D,4,0) -> 38 | H10: =+G10-D10 -> 24
A11: Урганч | B11: 19 | C11: 59 | D11: 21 | E11: =+VLOOKUP(A11,'q_2 district (черн)'!A:D,2,0) -> 21 | F11: =+VLOOKUP(A11,'q_2 district (черн)'!A:D,3,0) -> 38 | G11: =+VLOOKUP(A11,'q_2 district (черн)'!A:D,4,0) -> 42 | H11: =+G11-D11 -> 21
A12: Навбаҳор | B12: 17 | C12: 62 | D12: 21 | E12: =+VLOOKUP(A12,'q_2 district (черн)'!A:D,2,0) -> 19 | F12: =+VLOOKUP(A12,'q_2 district (черн)'!A:D,3,0) -> 40 | G12: =+VLOOKUP(A12,'q_2 district (черн)'!A:D,4,0) -> 41 | H12: =+G12-D12 -> 20
A13: Чортоқ | B13: 16 | C13: 67 | D13: 18 | E13: =+VLOOKUP(A13,'q_2 district (черн)'!A:D,2,0) -> 13 | F13: =+VLOOKUP(A13,'q_2 district (черн)'!A:D,3,0) -> 50 | G13: =+VLOOKUP(A13,'q_2 district (черн)'!A:D,4,0) -> 38 | H13: =+G13-D13 -> 20
A14: Шуманай | B14: 15 | C14: 76 | D14: 9 | E14: =+VLOOKUP(A14,'q_2 district (черн)'!A:D,2,0) -> 12 | F14: =+VLOOKUP(A14,'q_2 district (черн)'!A:D,3,0) -> 59 | G14: =+VLOOKUP(A14,'q_2 district (черн)'!A:D,4,0) -> 29 | H14: =+G14-D14 -> 20
A15: Қамаши | B15: 20 | C15: 68 | D15: 12 | E15: =+VLOOKUP(A15,'q_2 district (черн)'!A:D,2,0) -> 26 | F15: =+VLOOKUP(A15,'q_2 district (черн)'!A:D,3,0) -> 43 | G15: =+VLOOKUP(A15,'q_2 district (черн)'!A:D,4,0) -> 31 | H15: =+G15-D15 -> 19
A16: Қоракўл | B16: 27 | C16: 53 | D16: 20 | E16: =+VLOOKUP(A16,'q_2 district (черн)'!A:D,2,0) -> 16 | F16: =+VLOOKUP(A16,'q_2 district (черн)'!A:D,3,0) -> 44 | G16: =+VLOOKUP(A16,'q_2 district (черн)'!A:D,4,0) -> 39 | H16: =+G16-D16 -> 19
... A210: Учтепа | B210: 17 | C210: 53 | D210: 31 | E210: =+VLOOKUP(A210,'q_2 district (черн)'!A:D,2,0) -> 27 | F210: =+VLOOKUP(A210,'q_2 district (черн)'!A:D,3,0) -> 62 | G210: =+VLOOKUP(A210,'q_2 district (черн)'!A:D,4,0) -> 11 | H210: =+G210-D210 -> -20

Sheet q_2 district (черн)
B1: Август
A2: Ёзёвон | B2: 13 | C2: 61 | D2: 25
A3: Ўзбекистон | B3: 26 | C3: 46 | D3: 28
A4: Ўртачирчиқ | B4: 11 | C4: 58 | D4: 31
A5: Амударё | B5: 15 | C5: 49 | D5: 36
A6: Ангор | B6: 24 | C6: 47 | D6: 30
A7: Ангрен ш. | B7: 23 | C7: 56 | D7: 21
A8: Андижон | B8: 19 | C8: 52 | D8: 29
A9: Андижон ш. | B9: 22 | C9: 52 | D9: 26
A10: Арнасой | B10: 20 | C10: 47 | D10: 33
A11: Асака | B11: 20 | C11: 56 | D11: 24
A12: Балиқчи | B12: 13 | C12: 53 | D12: 33
A13: Бандихон | B13: 21 | C13: 44 | D13: 35
... A28: Бухоро ш. | B28: 22 | C28: 59 | D28: 19
A29: Бўзатов | C29: 42 | D29: 58
A30: Бўка | B30: 22 | C30: 45 | D30: 33
A31: Бўстон | B31: 5 | C31: 53 | D31: 43
A32: Бўстонлиқ | B32: 18 | C32: 68 | D32: 15
A33: Вобкент | B33: 22 | C33: 43 | D33: 35
A34: Гулистон | B34: 19 | C34: 49 | D34: 33
A35: Гулистон ш. | B35: 17 | C35: 63 | D35: 20
A36: Гурлан | B36: 13 | C36: 55 | D36: 32
A37: Данғара | B37: 23 | C37: 44 | D37: 33
A38: Денов | B38: 21 | C38: 53 | D38: 26
A39: Деҳқонобод | B39: 25 | C39: 51 | D39: 24
A40: Дўстлик | B40: 22 | C40: 47 | D40: 31
A41: Жалақудуқ | B41: 21 | C41: 47 | D41: 31
... A207: Республика бўйича ўртача | B207: 18 | C207: 52 | D207: 29

Sheet q_4
B3: 2025 йил май | E3: 2025 йил август
A4: district | B4: Камайди | C4: Ўзгармади | D4: Кўпайди | E4: Камайди | F4: Ўзгармади | G4: Кўпайди
A5: Хоразм вилояти | B5: 16 | C5: 37 | D5: 22 | E5: =+VLOOKUP(A5,'q_4 (черн)'!A:D,2,0) -> 19 | F5: =+VLOOKUP(A5,'q_4 (черн)'!A:D,3,0) -> 29 | G5: =+VLOOKUP(A5,'q_4 (черн)'!A:D,4,0) -> 30 | H5: =+G5-D5 -> 8
A6: Самарканд вилояти | B6: 14 | C6: 32 | D6: 26 | E6: =+VLOOKUP(A6,'q_4 (черн)'!A:D,2,0) -> 15 | F6: =+VLOOKUP(A6,'q_4 (черн)'!A:D,3,0) -> 29 | G6: =+VLOOKUP(A6,'q_4 (черн)'!A:D,4,0) -> 34 | H6: =+G6-D6 -> 8
A7: Сирдарё вилояти | B7: 14 | C7: 35 | D7: 24 | E7: =+VLOOKUP(A7,'q_4 (черн)'!A:D,2,0) -> 15 | F7: =+VLOOKUP(A7,'q_4 (черн)'!A:D,3,0) -> 26 | G7: =+VLOOKUP(A7,'q_4 (черн)'!A:D,4,0) -> 31 | H7: =+G7-D7 -> 7
A8: Бухоро вилояти | B8: 16 | C8: 35 | D8: 23 | E8: =+VLOOKUP(A8,'q_4 (черн)'!A:D,2,0) -> 16 | F8: =+VLOOKUP(A8,'q_4 (черн)'!A:D,3,0) -> 33 | G8: =+VLOOKUP(A8,'q_4 (черн)'!A:D,4,0) -> 29 | H8: =+G8-D8 -> 6
A9: Тошкент шахри | B9: 13 | C9: 26 | D9: 24 | E9: =+VLOOKUP(A9,'q_4 (черн)'!A:D,2,0) -> 16 | F9: =+VLOOKUP(A9,'q_4 (черн)'!A:D,3,0) -> 23 | G9: =+VLOOKUP(A9,'q_4 (черн)'!A:D,4,0) -> 29 | H9: =+G9-D9 -> 5
A10: Коракалпокистон Республикаси | B10: 16 | C10: 41 | D10: 20 | E10: =+VLOOKUP(A10,'q_4 (черн)'!A:D,2,0) -> 18 | F10: =+VLOOKUP(A10,'q_4 (черн)'!A:D,3,0) -> 34 | G10: =+VLOOKUP(A10,'q_4 (черн)'!A:D,4,0) -> 25 | H10: =+G10-D10 -> 5
A11: Тошкент вилояти | B11: 16 | C11: 31 | D11: 27 | E11: =+VLOOKUP(A11,'q_4 (черн)'!A:D,2,0) -> 14 | F11: =+VLOOKUP(A11,'q_4 (черн)'!A:D,3,0) -> 28 | G11: =+VLOOKUP(A11,'q_4 (черн)'!A:D,4,0) -> 32 | H11: =+G11-D11 -> 5
A12: Фаргона вилояти | B12: 16 | C12: 31 | D12: 26 | E12: =+VLOOKUP(A12,'q_4 (черн)'!A:D,2,0) -> 19 | F12: =+VLOOKUP(A12,'q_4 (черн)'!A:D,3,0) -> 26 | G12: =+VLOOKUP(A12,'q_4 (черн)'!A:D,4,0) -> 30 | H12: =+G12-D12 -> 4
A13: Навоий вилояти | B13: 15 | C13: 34 | D13: 26 | E13: =+VLOOKUP(A13,'q_4 (черн)'!A:D,2,0) -> 16 | F13: =+VLOOKUP(A13,'q_4 (черн)'!A:D,3,0) -> 32 | G13: =+VLOOKUP(A13,'q_4 (черн)'!A:D,4,0) -> 30 | H13: =+G13-D13 -> 4
A14: Наманган вилояти | B14: 15 | C14: 29 | D14: 30 | E14: =+VLOOKUP(A14,'q_4 (черн)'!A:D,2,0) -> 15 | F14: =+VLOOKUP(A14,'q_4 (черн)'!A:D,3,0) -> 32 | G14: =+VLOOKUP(A14,'q_4 (черн)'!A:D,4,0) -> 33 | H14: =+G14-D14 -> 3
A15: Сурхандарё вилояти | B15: 15 | C15: 34 | D15: 23 | E15: =+VLOOKUP(A15,'q_4 (черн)'!A:D,2,0) -> 17 | F15: =+VLOOKUP(A15,'q_4 (черн)'!A:D,3,0) -> 34 | G15: =+VLOOKUP(A15,'q_4 (черн)'!A:D,4,0) -> 26 | H15: =+G15-D15 -> 3
A16: Жиззах вилояти | B16: 13 | C16: 38 | D16: 27 | E16: =+VLOOKUP(A16,'q_4 (черн)'!A:D,2,0) -> 16 | F16: =+VLOOKUP(A16,'q_4 (черн)'!A:D,3,0) -> 34 | G16: =+VLOOKUP(A16,'q_4 (черн)'!A:D,4,0) -> 29 | H16: =+G16-D16 -> 2
... A18: Андижон вилояти | B18: 14 | C18: 27 | D18: 31 | E18: =+VLOOKUP(A18,'q_4 (черн)'!A:D,2,0) -> 18 | F18: =+VLOOKUP(A18,'q_4 (черн)'!A:D,3,0) -> 28 | G18: =+VLOOKUP(A18,'q_4 (черн)'!A:D,4,0) -> 31 | H18: =+G18-D18 -> 0
A19: Республика бўйича ўртача | B19: 15 | C19: 32 | D19: 26 | E19: =+VLOOKUP(A19,'q_4 (черн)'!A:D,2,0) -> 17 | F19: =+VLOOKUP(A19,'q_4 (черн)'!A:D,3,0) -> 30 | G19: =+VLOOKUP(A19,'q_4 (черн)'!A:D,4,0) -> 30

Sheet q_4 (черн)
B1: Август
A2: Андижон вилояти | B2: 18 | C2: 28 | D2: 31
A3: Бухоро вилояти | B3: 16 | C3: 33 | D3: 29
A4: Жиззах вилояти | B4: 16 | C4: 34 | D4: 29
A5: Кашкадарё вилояти | B5: 18 | C5: 35 | D5: 24
A6: Коракалпокистон Республикаси | B6: 18 | C6: 34 | D6: 25
A7: Навоий вилояти | B7: 16 | C7: 32 | D7: 30
A8: Наманган вилояти | B8: 15 | C8: 32 | D8: 33
A9: Самарканд вилояти | B9: 15 | C9: 29 | D9: 34
A10: Сирдарё вилояти | B10: 15 | C10: 26 | D10: 31
A11: Сурхандарё вилояти | B11: 17 | C11: 34 | D11: 26
A12: Тошкент вилояти | B12: 14 | C12: 28 | D12: 32
A13: Тошкент шахри | B13: 16 | C13: 23 | D13: 29
... A16: Республика бўйича ўртача | B16: 17 | C16: 30 | D16: 30

Sheet q_4 district
B3: 2025 йил май | E3: 2025 йил август
A4: district | B4: Камайди | C4: Ўзгармади | D4: Кўпайди | E4: Камайди | F4: Ўзгармади | G4: Кўпайди
A5: Конимех | B5: 15 | C5: 41 | D5: 17 | E5: =+VLOOKUP(A5,'q_4 district (черн)'!A:D,2,0) -> 12 | F5: =+VLOOKUP(A5,'q_4 district (черн)'!A:D,3,0) -> 28 | G5: =+VLOOKUP(A5,'q_4 district (черн)'!A:D,4,0) -> 50 | H5: =+G5-D5 -> 33
A6: Нурафшон ш. | B6: 10 | C6: 33 | D6: 23 | E6: =+VLOOKUP(A6,'q_4 district (черн)'!A:D,2,0) -> 12 | F6: =+VLOOKUP(A6,'q_4 district (черн)'!A:D,3,0) -> 20 | G6: =+VLOOKUP(A6,'q_4 district (черн)'!A:D,4,0) -> 51 | H6: =+G6-D6 -> 28
A7: Сирдарё | B7: 5 | C7: 40 | D7: 19 | E7: =+VLOOKUP(A7,'q_4 district (черн)'!A:D,2,0) -> 14 | F7: =+VLOOKUP(A7,'q_4 district (черн)'!A:D,3,0) -> 25 | G7: =+VLOOKUP(A7,'q_4 district (черн)'!A:D,4,0) -> 43 | H7: =+G7-D7 -> 24
A8: Тупроққальа | B8: 22 | C8: 38 | D8: 16 | E8: =+VLOOKUP(A8,'q_4 district (черн)'!A:D,2,0) -> 10 | F8: =+VLOOKUP(A8,'q_4 district (черн)'!A:D,3,0) -> 41 | G8: =+VLOOKUP(A8,'q_4 district (черн)'!A:D,4,0) -> 38 | H8: =+G8-D8 -> 22
A9: Бахмал | B9: 11 | C9: 51 | D9: 14 | E9: =+VLOOKUP(A9,'q_4 district (черн)'!A:D,2,0) -> 22 | F9: =+VLOOKUP(A9,'q_4 district (черн)'!A:D,3,0) -> 32 | G9: =+VLOOKUP(A9,'q_4 district (черн)'!A:D,4,0) -> 34 | H9: =+G9-D9 -> 20
A10: Бўзатов | B10: 28 | C10: 27 | D10: 4 | E10: =+VLOOKUP(A10,'q_4 district (черн)'!A:D,2,0) -> 24 | F10: =+VLOOKUP(A10,'q_4 district (черн)'!A:D,3,0) -> 49 | G10: =+VLOOKUP(A10,'q_4 district (черн)'!A:D,4,0) -> 24 | H10: =+G10-D10 -> 20
A11: Гулистон | B11: 15 | C11: 37 | D11: 21 | E11: =+VLOOKUP(A11,'q_4 district (черн)'!A:D,2,0) -> 15 | F11: =+VLOOKUP(A11,'q_4 district (черн)'!A:D,3,0) -> 24 | G11: =+VLOOKUP(A11,'q_4 district (черн)'!A:D,4,0) -> 41 | H11: =+G11-D11 -> 20
A12: Тойлоқ | B12: 11 | C12: 47 | D12: 19 | E12: =+VLOOKUP(A12,'q_4 district (черн)'!A:D,2,0) -> 13 | F12: =+VLOOKUP(A12,'q_4 district (черн)'!A:D,3,0) -> 34 | G12: =+VLOOKUP(A12,'q_4 district (черн)'!A:D,4,0) -> 38 | H12: =+G12-D12 -> 19
A13: Янгиариқ | B13: 13 | C13: 45 | D13: 15 | E13: =+VLOOKUP(A13,'q_4 district (черн)'!A:D,2,0) -> 16 | F13: =+VLOOKUP(A13,'q_4 district (черн)'!A:D,3,0) -> 32 | G13: =+VLOOKUP(A13,'q_4 district (черн)'!A:D,4,0) -> 33 | H13: =+G13-D13 -> 18
A14: Янгиер ш. | B14: 16 | C14: 41 | D14: 17 | E14: =+VLOOKUP(A14,'q_4 district (черн)'!A:D,2,0) -> 28 | F14: =+VLOOKUP(A14,'q_4 district (черн)'!A:D,3,0) -> 14 | G14: =+VLOOKUP(A14,'q_4 district (черн)'!A:D,4,0) -> 35 | H14: =+G14-D14 -> 18
A15: Хонобод ш. | B15: 35 | C15: 16 | D15: 26 | E15: =+VLOOKUP(A15,'q_4 district (черн)'!A:D,2,0) -> 18 | F15: =+VLOOKUP(A15,'q_4 district (черн)'!A:D,3,0) -> 33 | G15: =+VLOOKUP(A15,'q_4 district (черн)'!A:D,4,0) -> 43 | H15: =+G15-D15 -> 17
A16: Косонсой | B16: 21 | C16: 31 | D16: 24 | E16: =+VLOOKUP(A16,'q_4 district (черн)'!A:D,2,0) -> 15 | F16: =+VLOOKUP(A16,'q_4 district (черн)'!A:D,3,0) -> 32 | G16: =+VLOOKUP(A16,'q_4 district (черн)'!A:D,4,0) -> 40 | H16: =+G16-D16 -> 16
... A210: Шаҳрисабз | B210: 11 | C210: 32 | D210: 35 | E210: =+VLOOKUP(A210,'q_4 district (черн)'!A:D,2,0) -> 17 | F210: =+VLOOKUP(A210,'q_4 district (черн)'!A:D,3,0) -> 46 | G210: =+VLOOKUP(A210,'q_4 district (черн)'!A:D,4,0) -> 18 | H210: =+G210-D210 -> -17

Sheet q_4 district (черн)
B1: Август
A2: Ёзёвон | B2: 16 | C2: 25 | D2: 33
A3: Ўзбекистон | B3: 22 | C3: 21 | D3: 35
A4: Ўртачирчиқ | B4: 5 | C4: 27 | D4: 39
A5: Амударё | B5: 19 | C5: 31 | D5: 25
A6: Ангор | B6: 18 | C6: 22 | D6: 21
A7: Ангрен ш. | B7: 12 | C7: 26 | D7: 33
A8: Андижон | B8: 13 | C8: 30 | D8: 34
A9: Андижон ш. | B9: 15 | C9: 26 | D9: 30
A10: Арнасой | B10: 17 | C10: 30 | D10: 28
A11: Асака | B11: 25 | C11: 23 | D11: 30
A12: Балиқчи | B12: 21 | C12: 35 | D12: 23
A13: Бандихон | B13: 11 | C13: 44 | D13: 29
... A207: Республика бўйича ўртача | B207: 17 | C207: 30 | D207: 30

Sheet q_6
B3: 2025 йил май | E3: 2025 йил август
A4: district | B4: Йўқ | C4: Билмайман | D4: Ҳа | E4: Йўқ | F4: Билмайман | G4: Ҳа
A5: Самарканд вилояти | B5: 62 | C5: 4 | D5: 34 | E5: =+VLOOKUP(A5,'q_6 (черн)'!A:D,2,0) -> 54 | F5: =+VLOOKUP(A5,'q_6 (черн)'!A:D,3,0) -> 3 | G5: =+VLOOKUP(A5,'q_6 (черн)'!A:D,4,0) -> 43 | H5: =+G5-D5 -> 9
A6: Навоий вилояти | B6: 60 | C6: 4 | D6: 36 | E6: =+VLOOKUP(A6,'q_6 (черн)'!A:D,2,0) -> 51 | F6: =+VLOOKUP(A6,'q_6 (черн)'!A:D,3,0) -> 5 | G6: =+VLOOKUP(A6,'q_6 (черн)'!A:D,4,0) -> 44 | H6: =+G6-D6 -> 8
A7: Хоразм вилояти | B7: 63 | C7: 3 | D7: 34 | E7: =+VLOOKUP(A7,'q_6 (черн)'!A:D,2,0) -> 54 | F7: =+VLOOKUP(A7,'q_6 (черн)'!A:D,3,0) -> 5 | G7: =+VLOOKUP(A7,'q_6 (черн)'!A:D,4,0) -> 41 | H7: =+G7-D7 -> 7
A8: Наманган вилояти | B8: 62 | C8: 2 | D8: 36 | E8: =+VLOOKUP(A8,'q_6 (черн)'!A:D,2,0) -> 53 | F8: =+VLOOKUP(A8,'q_6 (черн)'!A:D,3,0) -> 4 | G8: =+VLOOKUP(A8,'q_6 (черн)'!A:D,4,0) -> 43 | H8: =+G8-D8 -> 7
A9: Бухоро вилояти | B9: 59 | C9: 3 | D9: 38 | E9: =+VLOOKUP(A9,'q_6 (черн)'!A:D,2,0) -> 53 | F9: =+VLOOKUP(A9,'q_6 (черн)'!A:D,3,0) -> 2 | G9: =+VLOOKUP(A9,'q_6 (черн)'!A:D,4,0) -> 45 | H9: =+G9-D9 -> 7
A10: Коракалпокистон Республикаси | B10: 61 | C10: 3 | D10: 36 | E10: =+VLOOKUP(A10,'q_6 (черн)'!A:D,2,0) -> 53 | F10: =+VLOOKUP(A10,'q_6 (черн)'!A:D,3,0) -> 5 | G10: =+VLOOKUP(A10,'q_6 (черн)'!A:D,4,0) -> 43 | H10: =+G10-D10 -> 7
A11: Жиззах вилояти | B11: 63 | C11: 2 | D11: 35 | E11: =+VLOOKUP(A11,'q_6 (черн)'!A:D,2,0) -> 55 | F11: =+VLOOKUP(A11,'q_6 (черн)'!A:D,3,0) -> 3 | G11: =+VLOOKUP(A11,'q_6 (черн)'!A:D,4,0) -> 42 | H11: =+G11-D11 -> 7
A12: Тошкент шахри | B12: 63 | C12: 2 | D12: 35 | E12: =+VLOOKUP(A12,'q_6 (черн)'!A:D,2,0) -> 54 | F12: =+VLOOKUP(A12,'q_6 (черн)'!A:D,3,0) -> 5 | G12: =+VLOOKUP(A12,'q_6 (черн)'!A:D,4,0) -> 41 | H12: =+G12-D12 -> 6
A13: Фаргона вилояти | B13: 63 | C13: 3 | D13: 34 | E13: =+VLOOKUP(A13,'q_6 (черн)'!A:D,2,0) -> 56 | F13: =+VLOOKUP(A13,'q_6 (черн)'!A:D,3,0) -> 3 | G13: =+VLOOKUP(A13,'q_6 (черн)'!A:D,4,0) -> 40 | H13: =+G13-D13 -> 6
A14: Сурхандарё вилояти | B14: 59 | C14: 5 | D14: 36 | E14: =+VLOOKUP(A14,'q_6 (черн)'!A:D,2,0) -> 54 | F14: =+VLOOKUP(A14,'q_6 (черн)'!A:D,3,0) -> 4 | G14: =+VLOOKUP(A14,'q_6 (черн)'!A:D,4,0) -> 42 | H14: =+G14-D14 -> 6
A15: Тошкент вилояти | B15: 63 | C15: 3 | D15: 34 | E15: =+VLOOKUP(A15,'q_6 (черн)'!A:D,2,0) -> 59 | F15: =+VLOOKUP(A15,'q_6 (черн)'!A:D,3,0) -> 4 | G15: =+VLOOKUP(A15,'q_6 (черн)'!A:D,4,0) -> 38 | H15: =+G15-D15 -> 4
A16: Андижон вилояти | B16: 60 | C16: 3 | D16: 37 | E16: =+VLOOKUP(A16,'q_6 (черн)'!A:D,2,0) -> 55 | F16: =+VLOOKUP(A16,'q_6 (черн)'!A:D,3,0) -> 5 | G16: =+VLOOKUP(A16,'q_6 (черн)'!A:D,4,0) -> 40 | H16: =+G16-D16 -> 3
... A18: Кашкадарё вилояти | B18: 60 | C18: 5 | D18: 36 | E18: =+VLOOKUP(A18,'q_6 (черн)'!A:D,2,0) -> 58 | F18: =+VLOOKUP(A18,'q_6 (черн)'!A:D,3,0) -> 5 | G18: =+VLOOKUP(A18,'q_6 (черн)'!A:D,4,0) -> 37 | H18: =+G18-D18 -> 1
A19: Республика бўйича ўртача | B19: 61 | C19: 3 | D19: 35 | E19: =+VLOOKUP(A19,'q_6 (черн)'!A:D,2,0) -> 55 | F19: =+VLOOKUP(A19,'q_6 (черн)'!A:D,3,0) -> 4 | G19: =+VLOOKUP(A19,'q_6 (черн)'!A:D,4,0) -> 41

Sheet q_6 (черн)
B1: Август
A2: district | B2: Йўқ | C2: Билмайман | D2: Ҳа
A3: Андижон вилояти | B3: 55 | C3: 5 | D3: 40
A4: Бухоро вилояти | B4: 53 | C4: 2 | D4: 45
A5: Жиззах вилояти | B5: 55 | C5: 3 | D5: 42
A6: Кашкадарё вилояти | B6: 58 | C6: 5 | D6: 37
A7: Коракалпокистон Республикаси | B7: 53 | C7: 5 | D7: 43
A8: Навоий вилояти | B8: 51 | C8: 5 | D8: 44
A9: Наманган вилояти | B9: 53 | C9: 4 | D9: 43
A10: Самарканд вилояти | B10: 54 | C10: 3 | D10: 43
A11: Сирдарё вилояти | B11: 59 | C11: 4 | D11: 38
A12: Сурхандарё вилояти | B12: 54 | C12: 4 | D12: 42
A13: Тошкент вилояти | B13: 59 | C13: 4 | D13: 38
A14: Тошкент шахри | B14: 54 | C14: 5 | D14: 41
... A17: Республика бўйича ўртача | B17: 55 | C17: 4 | D17: 41

Sheet q_6 district
B3: 2025 йил май | E3: 2025 йил август
A4: district | B4: Йўқ | C4: Билмайман | D4: Ҳа | E4: Йўқ | F4: Билмайман | G4: Ҳа
A5: Амударё | B5: 59 | C5: 5 | D5: 36 | E5: =+VLOOKUP(A5,'q_6 district (черн)'!A:D,2,0) -> 38 | F5: =+VLOOKUP(A5,'q_6 district (черн)'!A:D,3,0) -> 8 | G5: =+VLOOKUP(A5,'q_6 district (черн)'!A:D,4,0) -> 54
A6: Ангор | B6: 54 | C6: 11 | D6: 35 | E6: =+VLOOKUP(A6,'q_6 district (черн)'!A:D,2,0) -> 48 | F6: =+VLOOKUP(A6,'q_6 district (черн)'!A:D,3,0) -> 7 | G6: =+VLOOKUP(A6,'q_6 district (черн)'!A:D,4,0) -> 44
A7: Ангрен ш. | B7: 63 | C7: 7 | D7: 30 | E7: =+VLOOKUP(A7,'q_6 district (черн)'!A:D,2,0) -> 61 | F7: =+VLOOKUP(A7,'q_6 district (черн)'!A:D,3,0) -> 9 | G7: =+VLOOKUP(A7,'q_6 district (черн)'!A:D,4,0) -> 30
A8: Андижон | B8: 59 | C8: 3 | D8: 38 | E8: =+VLOOKUP(A8,'q_6 district (черн)'!A:D,2,0) -> 49 | F8: =+VLOOKUP(A8,'q_6 district (черн)'!A:D,3,0) -> 7 | G8: =+VLOOKUP(A8,'q_6 district (черн)'!A:D,4,0) -> 44
A9: Андижон ш. | B9: 59 | C9: 4 | D9: 37 | E9: =+VLOOKUP(A9,'q_6 district (черн)'!A:D,2,0) -> 57 | F9: =+VLOOKUP(A9,'q_6 district (черн)'!A:D,3,0) -> 5 | G9: =+VLOOKUP(A9,'q_6 district (черн)'!A:D,4,0) -> 38
A10: Арнасой | B10: 64 | C10: 1 | D10: 35 | E10: =+VLOOKUP(A10,'q_6 district (черн)'!A:D,2,0) -> 62 | F10: =+VLOOKUP(A10,'q_6 district (черн)'!A:D,3,0) -> 0 | G10: =+VLOOKUP(A10,'q_6 district (черн)'!A:D,4,0) -> 38
A11: Асака | B11: 60 | C11: 5 | D11: 35 | E11: =+VLOOKUP(A11,'q_6 district (черн)'!A:D,2,0) -> 65 | F11: =+VLOOKUP(A11,'q_6 district (черн)'!A:D,3,0) -> 2 | G11: =+VLOOKUP(A11,'q_6 district (черн)'!A:D,4,0) -> 33
A12: Балиқчи | B12: 58 | C12: 6 | D12: 36 | E12: =+VLOOKUP(A12,'q_6 district (черн)'!A:D,2,0) -> 50 | F12: =+VLOOKUP(A12,'q_6 district (черн)'!A:D,3,0) -> 4 | G12: =+VLOOKUP(A12,'q_6 district (черн)'!A:D,4,0) -> 45
A13: Бандихон | B13: 46 | D13: 54 | E13: =+VLOOKUP(A13,'q_6 district (черн)'!A:D,2,0) -> 47 | F13: =+VLOOKUP(A13,'q_6 district (черн)'!A:D,3,0) -> 1 | G13: =+VLOOKUP(A13,'q_6 district (черн)'!A:D,4,0) -> 52
A14: Бахмал | B14: 69 | D14: 31 | E14: =+VLOOKUP(A14,'q_6 district (черн)'!A:D,2,0) -> 41 | F14: =+VLOOKUP(A14,'q_6 district (черн)'!A:D,3,0) -> 3 | G14: =+VLOOKUP(A14,'q_6 district (черн)'!A:D,4,0) -> 55
A15: Бекобод | B15: 59 | C15: 3 | D15: 38 | E15: =+VLOOKUP(A15,'q_6 district (черн)'!A:D,2,0) -> 60 | F15: =+VLOOKUP(A15,'q_6 district (черн)'!A:D,3,0) -> 2 | G15: =+VLOOKUP(A15,'q_6 district (черн)'!A:D,4,0) -> 37
A16: Бекобод ш. | B16: 68 | C16: 1 | D16: 31 | E16: =+VLOOKUP(A16,'q_6 district (черн)'!A:D,2,0) -> 58 | F16: =+VLOOKUP(A16,'q_6 district (черн)'!A:D,3,0) -> 0 | G16: =+VLOOKUP(A16,'q_6 district (черн)'!A:D,4,0) -> 42
A17: Бектемир | B17: 56 | C17: 3 | D17: 41 | E17: =+VLOOKUP(A17,'q_6 district (черн)'!A:D,2,0) -> 35 | F17: =+VLOOKUP(A17,'q_6 district (черн)'!A:D,3,0) -> 6 | G17: =+VLOOKUP(A17,'q_6 district (черн)'!A:D,4,0) -> 59
A18: Беруний | B18: 63 | C18: 1 | D18: 36 | E18: =+VLOOKUP(A18,'q_6 district (черн)'!A:D,2,0) -> 56 | F18: =+VLOOKUP(A18,'q_6 district (черн)'!A:D,3,0) -> 3 | G18: =+VLOOKUP(A18,'q_6 district (черн)'!A:D,4,0) -> 41
A19: Бешариқ | B19: 69 | C19: 2 | D19: 29 | E19: =+VLOOKUP(A19,'q_6 district (черн)'!A:D,2,0) -> 60 | F19: =+VLOOKUP(A19,'q_6 district (черн)'!A:D,3,0) -> 5 | G19: =+VLOOKUP(A19,'q_6 district (черн)'!A:D,4,0) -> 35
A20: Боғдод | B20: 63 | C20: 3 | D20: 34 | E20: =+VLOOKUP(A20,'q_6 district (черн)'!A:D,2,0) -> 45 | F20: =+VLOOKUP(A20,'q_6 district (черн)'!A:D,3,0) -> 4 | G20: =+VLOOKUP(A20,'q_6 district (черн)'!A:D,4,0) -> 51
A21: Боғот | B21: 60 | C21: 4 | D21: 36 | E21: =+VLOOKUP(A21,'q_6 district (черн)'!A:D,2,0) -> 58 | F21: =+VLOOKUP(A21,'q_6 district (черн)'!A:D,3,0) -> 8 | G21: =+VLOOKUP(A21,'q_6 district (черн)'!A:D,4,0) -> 34
A22: Боёвут | B22: 71 | C22: 1 | D22: 28 | E22: =+VLOOKUP(A22,'q_6 district (черн)'!A:D,2,0) -> 71 | F22: =+VLOOKUP(A22,'q_6 district (черн)'!A:D,3,0) -> 2 | G22: =+VLOOKUP(A22,'q_6 district (черн)'!A:D,4,0) -> 27
A23: Бойсун | B23: 52 | C23: 12 | D23: 36 | E23: =+VLOOKUP(A23,'q_6 district (черн)'!A:D,2,0) -> 66 | F23: =+VLOOKUP(A23,'q_6 district (черн)'!A:D,3,0) -> 6 | G23: =+VLOOKUP(A23,'q_6 district (черн)'!A:D,4,0) -> 28
A24: Бувайда | B24: 66 | C24: 5 | D24: 29 | E24: =+VLOOKUP(A24,'q_6 district (черн)'!A:D,2,0) -> 56 | F24: =+VLOOKUP(A24,'q_6 district (черн)'!A:D,3,0) -> 3 | G24: =+VLOOKUP(A24,'q_6 district (черн)'!A:D,4,0) -> 42
A25: Бўзатов | B25: 88 | D25: 12 | E25: =+VLOOKUP(A25,'q_6 district (черн)'!A:D,2,0) -> 71 | F25: =+VLOOKUP(A25,'q_6 district (черн)'!A:D,3,0) -> 0 | G25: =+VLOOKUP(A25,'q_6 district (черн)'!A:D,4,0) -> 29
A26: Бўка | B26: 73 | C26: 4 | D26: 23 | E26: =+VLOOKUP(A26,'q_6 district (черн)'!A:D,2,0) -> 63 | F26: =+VLOOKUP(A26,'q_6 district (черн)'!A:D,3,0) -> 4 | G26: =+VLOOKUP(A26,'q_6 district (черн)'!A:D,4,0) -> 33
A27: Булоқбоши | B27: 67 | C27: 3 | D27: 30 | E27: =+VLOOKUP(A27,'q_6 district (черн)'!A:D,2,0) -> 47 | F27: =+VLOOKUP(A27,'q_6 district (черн)'!A:D,3,0) -> 6 | G27: =+VLOOKUP(A27,'q_6 district (черн)'!A:D,4,0) -> 47
A28: Булунғур | B28: 64 | C28: 4 | D28: 32 | E28: =+VLOOKUP(A28,'q_6 district (черн)'!A:D,2,0) -> 54 | F28: =+VLOOKUP(A28,'q_6 district (черн)'!A:D,3,0) -> 0 | G28: =+VLOOKUP(A28,'q_6 district (черн)'!A:D,4,0) -> 46
A29: Бўстон | B29: 60 | C29: 2 | D29: 38 | E29: =+VLOOKUP(A29,'q_6 district (черн)'!A:D,2,0) -> 37 | F29: =+VLOOKUP(A29,'q_6 district (черн)'!A:D,3,0) -> 7 | G29: =+VLOOKUP(A29,'q_6 district (черн)'!A:D,4,0) -> 56
A30: Бўстонлиқ | B30: 66 | C30: 5 | D30: 29 | E30: =+VLOOKUP(A30,'q_6 district (черн)'!A:D,2,0) -> 66 | F30: =+VLOOKUP(A30,'q_6 district (черн)'!A:D,3,0) -> 4 | G30: =+VLOOKUP(A30,'q_6 district (черн)'!A:D,4,0) -> 30
A31: Бухоро тумани | B31: 64 | C31: 6 | D31: 30 | E31: =+VLOOKUP(A31,'q_6 district (черн)'!A:D,2,0) -> 61 | F31: =+VLOOKUP(A31,'q_6 district (черн)'!A:D,3,0) -> 3 | G31: =+VLOOKUP(A31,'q_6 district (черн)'!A:D,4,0) -> 36
A32: Бухоро ш. | B32: 57 | C32: 2 | D32: 41 | E32: =+VLOOKUP(A32,'q_6 district (черн)'!A:D,2,0) -> 62 | F32: =+VLOOKUP(A32,'q_6 district (черн)'!A:D,3,0) -> 1 | G32: =+VLOOKUP(A32,'q_6 district (черн)'!A:D,4,0) -> 37
A33: Вобкент | B33: 62 | C33: 4 | D33: 34 | E33: =+VLOOKUP(A33,'q_6 district (черн)'!A:D,2,0) -> 55 | F33: =+VLOOKUP(A33,'q_6 district (черн)'!A:D,3,0) -> 2 | G33: =+VLOOKUP(A33,'q_6 district (черн)'!A:D,4,0) -> 44
A34: Ғаллаорол | B34: 59 | C34: 2 | D34: 39 | E34: =+VLOOKUP(A34,'q_6 district (черн)'!A:D,2,0) -> 61 | F34: =+VLOOKUP(A34,'q_6 district (черн)'!A:D,3,0) -> 1 | G34: =+VLOOKUP(A34,'q_6 district (черн)'!A:D,4,0) -> 38
A35: Ғиждувон | B35: 65 | C35: 3 | D35: 32 | E35: =+VLOOKUP(A35,'q_6 district (черн)'!A:D,2,0) -> 47 | F35: =+VLOOKUP(A35,'q_6 district (черн)'!A:D,3,0) -> 1 | G35: =+VLOOKUP(A35,'q_6 district (черн)'!A:D,4,0) -> 52
A36: Ғузор | B36: 62 | C36: 8 | D36: 30 | E36: =+VLOOKUP(A36,'q_6 district (черн)'!A:D,2,0) -> 69 | F36: =+VLOOKUP(A36,'q_6 district (черн)'!A:D,3,0) -> 1 | G36: =+VLOOKUP(A36,'q_6 district (черн)'!A:D,4,0) -> 30
A37: Гулистон | B37: 63 | C37: 4 | D37: 33 | E37: =+VLOOKUP(A37,'q_6 district (черн)'!A:D,2,0) -> 49 | F37: =+VLOOKUP(A37,'q_6 district (черн)'!A:D,3,0) -> 7 | G37: =+VLOOKUP(A37,'q_6 district (черн)'!A:D,4,0) -> 44
A38: Гулистон ш. | B38: 65 | D38: 35 | E38: =+VLOOKUP(A38,'q_6 district (черн)'!A:D,2,0) -> 60 | F38: =+VLOOKUP(A38,'q_6 district (черн)'!A:D,3,0) -> 3 | G38: =+VLOOKUP(A38,'q_6 district (черн)'!A:D,4,0) -> 37
A39: Гурлан | B39: 55 | C39: 3 | D39: 42 | E39: =+VLOOKUP(A39,'q_6 district (черн)'!A:D,2,0) -> 39 | F39: =+VLOOKUP(A39,'q_6 district (черн)'!A:D,3,0) -> 6 | G39: =+VLOOKUP(A39,'q_6 district (черн)'!A:D,4,0) -> 54
A40: Данғара | B40: 60 | C40: 1 | D40: 39 | E40: =+VLOOKUP(A40,'q_6 district (черн)'!A:D,2,0) -> 59 | F40: =+VLOOKUP(A40,'q_6 district (черн)'!A:D,3,0) -> 3 | G40: =+VLOOKUP(A40,'q_6 district (черн)'!A:D,4,0) -> 37
A41: Денов | B41: 67 | C41: 1 | D41: 32 | E41: =+VLOOKUP(A41,'q_6 district (черн)'!A:D,2,0) -> 54 | F41: =+VLOOKUP(A41,'q_6 district (черн)'!A:D,3,0) -> 4 | G41: =+VLOOKUP(A41,'q_6 district (черн)'!A:D,4,0) -> 41
A42: Деҳқонобод | B42: 63 | C42: 3 | D42: 35 | E42: =+VLOOKUP(A42,'q_6 district (черн)'!A:D,2,0) -> 61 | F42: =+VLOOKUP(A42,'q_6 district (черн)'!A:D,3,0) -> 12 | G42: =+VLOOKUP(A42,'q_6 district (черн)'!A:D,4,0) -> 27
...

Sheet q_6 district (черн)
B1: Август
A2: district | B2: Йўқ | C2: Билмайман | D2: Ҳа
A3: Ёзёвон | B3: 57 | C3: 4 | D3: 40
A4: Ўзбекистон | B4: 64 | C4: 3 | D4: 33
A5: Ўртачирчиқ | B5: 56 | C5: 3 | D5: 41
A6: Амударё | B6: 38 | C6: 8 | D6: 54
A7: Ангор | B7: 48 | C7: 7 | D7: 44
A8: Ангрен ш. | B8: 61 | C8: 9 | D8: 30
A9: Андижон | B9: 49 | C9: 7 | D9: 44
A10: Андижон ш. | B10: 57 | C10: 5 | D10: 38
A11: Арнасой | B11: 62 | D11: 38
A12: Асака | B12: 65 | C12: 2 | D12: 33
A13: Балиқчи | B13: 50 | C13: 4 | D13: 45
A14: Бандихон | B14: 47 | C14: 1 | D14: 52
A15: Бахмал | B15: 41 | C15: 3 | D15: 55
A16: Бекобод | B16: 60 | C16: 2 | D16: 37
A17: Бекобод ш. | B17: 58 | D17: 42
A18: Бектемир | B18: 35 | C18: 6 | D18: 59
A19: Беруний | B19: 56 | C19: 3 | D19: 41
A20: Бешариқ | B20: 60 | C20: 5 | D20: 35
A21: Бойсун | B21: 66 | C21: 6 | D21: 28
A22: Боёвут | B22: 71 | C22: 2 | D22: 27
A23: Боғдод | B23: 45 | C23: 4 | D23: 51
A24: Боғот | B24: 58 | C24: 8 | D24: 34
A25: Бувайда | B25: 56 | C25: 3 | D25: 42
A26: Булоқбоши | B26: 47 | C26: 6 | D26: 47
A27: Булунғур | B27: 54 | D27: 46
A28: Бухоро тумани | B28: 61 | C28: 3 | D28: 36
A29: Бухоро ш. | B29: 62 | C29: 1 | D29: 37
A30: Бўзатов | B30: 71 | D30: 29
A31: Бўка | B31: 63 | C31: 4 | D31: 33
A32: Бўстон | B32: 37 | C32: 7 | D32: 56
A33: Бўстонлиқ | B33: 66 | C33: 4 | D33: 30
A34: Вобкент | B34: 55 | C34: 2 | D34: 44
A35: Гулистон | B35: 49 | C35: 7 | D35: 44
A36: Гулистон ш. | B36: 60 | C36: 3 | D36: 37
A37: Гурлан | B37: 39 | C37: 6 | D37: 54
A38: Данғара | B38: 59 | C38: 3 | D38: 37
A39: Денов | B39: 54 | C39: 4 | D39: 41
A40: Деҳқонобод | B40: 61 | C40: 12 | D40: 27
...

Sheet q_1
B3: 2025 йил май | E3: 2025 йил август
A4: district | B4: Ёмонлашади | C4: Ўзгармайди | D4: Яхшиланади | E4: Ёмонлашади | F4: Ўзгармайди | G4: Яхшиланади
A5: Кашкадарё вилояти | B5: 8 | C5: 16 | D5: 50 | E5: =+VLOOKUP(A5,'q_1 (черн)'!A:D,2,0) -> 8 | F5: =+VLOOKUP(A5,'q_1 (черн)'!A:D,3,0) -> 20 | G5: =+VLOOKUP(A5,'q_1 (черн)'!A:D,4,0) -> 48
A6: Тошкент шахри | B6: 12 | C6: 23 | D6: 45 | E6: =+VLOOKUP(A6,'q_1 (черн)'!A:D,2,0) -> 9 | F6: =+VLOOKUP(A6,'q_1 (черн)'!A:D,3,0) -> 22 | G6: =+VLOOKUP(A6,'q_1 (черн)'!A:D,4,0) -> 48
A7: Андижон вилояти | B7: 6 | C7: 16 | D7: 54 | E7: =+VLOOKUP(A7,'q_1 (черн)'!A:D,2,0) -> 9 | F7: =+VLOOKUP(A7,'q_1 (черн)'!A:D,3,0) -> 16 | G7: =+VLOOKUP(A7,'q_1 (черн)'!A:D,4,0) -> 54
A8: Хоразм вилояти | B8: 10 | C8: 17 | D8: 53 | E8: =+VLOOKUP(A8,'q_1 (черн)'!A:D,2,0) -> 10 | F8: =+VLOOKUP(A8,'q_1 (черн)'!A:D,3,0) -> 23 | G8: =+VLOOKUP(A8,'q_1 (черн)'!A:D,4,0) -> 52
A9: Самарканд вилояти | B9: 7 | C9: 18 | D9: 55 | E9: =+VLOOKUP(A9,'q_1 (черн)'!A:D,2,0) -> 6 | F9: =+VLOOKUP(A9,'q_1 (черн)'!A:D,3,0) -> 17 | G9: =+VLOOKUP(A9,'q_1 (черн)'!A:D,4,0) -> 56
A10: Наманган вилояти | B10: 8 | C10: 14 | D10: 60 | E10: =+VLOOKUP(A10,'q_1 (черн)'!A:D,2,0) -> 8 | F10: =+VLOOKUP(A10,'q_1 (черн)'!A:D,3,0) -> 16 | G10: =+VLOOKUP(A10,'q_1 (черн)'!A:D,4,0) -> 62
A11: Фаргона вилояти | B11: 8 | C11: 15 | D11: 54 | E11: =+VLOOKUP(A11,'q_1 (черн)'!A:D,2,0) -> 9 | F11: =+VLOOKUP(A11,'q_1 (черн)'!A:D,3,0) -> 18 | G11: =+VLOOKUP(A11,'q_1 (черн)'!A:D,4,0) -> 53
A12: Бухоро вилояти | B12: 10 | C12: 18 | D12: 51 | E12: =+VLOOKUP(A12,'q_1 (черн)'!A:D,2,0) -> 8 | F12: =+VLOOKUP(A12,'q_1 (черн)'!A:D,3,0) -> 19 | G12: =+VLOOKUP(A12,'q_1 (черн)'!A:D,4,0) -> 55
A13: Коракалпокистон Республикаси | B13: 7 | C13: 18 | D13: 55 | E13: =+VLOOKUP(A13,'q_1 (черн)'!A:D,2,0) -> 6 | F13: =+VLOOKUP(A13,'q_1 (черн)'!A:D,3,0) -> 20 | G13: =+VLOOKUP(A13,'q_1 (черн)'!A:D,4,0) -> 52
A14: Тошкент вилояти | B14: 11 | C14: 17 | D14: 47 | E14: =+VLOOKUP(A14,'q_1 (черн)'!A:D,2,0) -> 10 | F14: =+VLOOKUP(A14,'q_1 (черн)'!A:D,3,0) -> 19 | G14: =+VLOOKUP(A14,'q_1 (черн)'!A:D,4,0) -> 49
A15: Жиззах вилояти | B15: 7 | C15: 17 | D15: 58 | E15: =+VLOOKUP(A15,'q_1 (черн)'!A:D,2,0) -> 6 | F15: =+VLOOKUP(A15,'q_1 (черн)'!A:D,3,0) -> 19 | G15: =+VLOOKUP(A15,'q_1 (черн)'!A:D,4,0) -> 58
A16: Сирдарё вилояти | B16: 7 | C16: 18 | D16: 52 | E16: =+VLOOKUP(A16,'q_1 (черн)'!A:D,2,0) -> 7 | F16: =+VLOOKUP(A16,'q_1 (черн)'!A:D,3,0) -> 15 | G16: =+VLOOKUP(A16,'q_1 (черн)'!A:D,4,0) -> 57
... A19: Республика бўйича ўртача | B19: 8 | C19: 17 | D19: 53 | E19: =+VLOOKUP(A19,'q_1 (черн)'!A:D,2,0) -> 8 | F19: =+VLOOKUP(A19,'q_1 (черн)'!A:D,3,0) -> 18 | G19: =+VLOOKUP(A19,'q_1 (черн)'!A:D,4,0) -> 53

Sheet q_1 (черн)
B1: Август
A2: district | B2: Ёмонлашади | C2: Ўзгармайди | D2: Яхшиланади
A3: Андижон вилояти | B3: 9 | C3: 16 | D3: 54
A4: Бухоро вилояти | B4: 8 | C4: 19 | D4: 55
A5: Жиззах вилояти | B5: 6 | C5: 19 | D5: 58
A6: Кашкадарё вилояти | B6: 8 | C6: 20 | D6: 48
A7: Коракалпокистон Республикаси | B7: 6 | C7: 20 | D7: 52
A8: Навоий вилояти | B8: 7 | C8: 23 | D8: 50
A9: Наманган вилояти | B9: 8 | C9: 16 | D9: 62
A10: Самарканд вилояти | B10: 6 | C10: 17 | D10: 56
A11: Сирдарё вилояти | B11: 7 | C11: 15 | D11: 57
A12: Сурхандарё вилояти | B12: 11 | C12: 14 | D12: 53
A13: Тошкент вилояти | B13: 10 | C13: 19 | D13: 49
A14: Тошкент шахри | B14: 9 | C14: 22 | D14: 48
... A17: Республика бўйича ўртача | B17: 8 | C17: 18 | D17: 53

Sheet q_1 district
B3: 2025 йил май | E3: 2025 йил август
A4: district | B4: Ёмонлашади | C4: Ўзгармайди | D4: Яхшиланади | E4: Ёмонлашади | F4: Ўзгармайди | G4: Яхшиланади
A5: Амударё | B5: 10 | C5: 16 | D5: 46 | E5: =+VLOOKUP(A5,'q_1 district (черн)'!A:D,2,0) -> 4 | F5: =+VLOOKUP(A5,'q_1 district (черн)'!A:D,3,0) -> 18 | G5: =+VLOOKUP(A5,'q_1 district (черн)'!A:D,4,0) -> 52
A6: Ангор | B6: 3 | C6: 16 | D6: 61 | E6: =+VLOOKUP(A6,'q_1 district (черн)'!A:D,2,0) -> 9 | F6: =+VLOOKUP(A6,'q_1 district (черн)'!A:D,3,0) -> 14 | G6: =+VLOOKUP(A6,'q_1 district (черн)'!A:D,4,0) -> 56
A7: Ангрен ш. | B7: 8 | C7: 23 | D7: 45 | E7: =+VLOOKUP(A7,'q_1 district (черн)'!A:D,2,0) -> 8 | F7: =+VLOOKUP(A7,'q_1 district (черн)'!A:D,3,0) -> 28 | G7: =+VLOOKUP(A7,'q_1 district (черн)'!A:D,4,0) -> 48
A8: Андижон | B8: 4 | C8: 17 | D8: 63 | E8: =+VLOOKUP(A8,'q_1 district (черн)'!A:D,2,0) -> 6 | F8: =+VLOOKUP(A8,'q_1 district (черн)'!A:D,3,0) -> 17 | G8: =+VLOOKUP(A8,'q_1 district (черн)'!A:D,4,0) -> 51
A9: Андижон ш. | B9: 8 | C9: 19 | D9: 44 | E9: =+VLOOKUP(A9,'q_1 district (черн)'!A:D,2,0) -> 10 | F9: =+VLOOKUP(A9,'q_1 district (черн)'!A:D,3,0) -> 12 | G9: =+VLOOKUP(A9,'q_1 district (черн)'!A:D,4,0) -> 53
A10: Арнасой | B10: 5 | C10: 9 | D10: 62 | E10: =+VLOOKUP(A10,'q_1 district (черн)'!A:D,2,0) -> 10 | F10: =+VLOOKUP(A10,'q_1 district (черн)'!A:D,3,0) -> 20 | G10: =+VLOOKUP(A10,'q_1 district (черн)'!A:D,4,0) -> 57
A11: Асака | B11: 7 | C11: 15 | D11: 49 | E11: =+VLOOKUP(A11,'q_1 district (черн)'!A:D,2,0) -> 8 | F11: =+VLOOKUP(A11,'q_1 district (черн)'!A:D,3,0) -> 19 | G11: =+VLOOKUP(A11,'q_1 district (черн)'!A:D,4,0) -> 50
A12: Балиқчи | B12: 4 | C12: 19 | D12: 50 | E12: =+VLOOKUP(A12,'q_1 district (черн)'!A:D,2,0) -> 6 | F12: =+VLOOKUP(A12,'q_1 district (черн)'!A:D,3,0) -> 16 | G12: =+VLOOKUP(A12,'q_1 district (черн)'!A:D,4,0) -> 61
A13: Бандихон | B13: 7 | C13: 13 | D13: 55 | E13: =+VLOOKUP(A13,'q_1 district (черн)'!A:D,2,0) -> 11 | F13: =+VLOOKUP(A13,'q_1 district (черн)'!A:D,3,0) -> 13 | G13: =+VLOOKUP(A13,'q_1 district (черн)'!A:D,4,0) -> 56
A14: Бахмал | B14: 9 | C14: 14 | D14: 57 | E14: =+VLOOKUP(A14,'q_1 district (черн)'!A:D,2,0) -> 4 | F14: =+VLOOKUP(A14,'q_1 district (черн)'!A:D,3,0) -> 14 | G14: =+VLOOKUP(A14,'q_1 district (черн)'!A:D,4,0) -> 65
A15: Бекобод | B15: 12 | C15: 16 | D15: 60 | E15: =+VLOOKUP(A15,'q_1 district (черн)'!A:D,2,0) -> 9 | F15: =+VLOOKUP(A15,'q_1 district (черн)'!A:D,3,0) -> 19 | G15: =+VLOOKUP(A15,'q_1 district (черн)'!A:D,4,0) -> 55
A16: Бекобод ш. | B16: 14 | C16: 17 | D16: 40 | E16: =+VLOOKUP(A16,'q_1 district (черн)'!A:D,2,0) -> 3 | F16: =+VLOOKUP(A16,'q_1 district (черн)'!A:D,3,0) -> 17 | G16: =+VLOOKUP(A16,'q_1 district (черн)'!A:D,4,0) -> 58
... A98: Музробод | B98: 6 | C98: 10 | D98: 56 | E98: =+VLOOKUP(A98,'q_1 district (черн)'!A:D,2,0) -> 14 | F98: =+VLOOKUP(A98,'q_1 district (черн)'!A:D,3,0) -> 15 | G98: =+VLOOKUP(A98,'q_1 district (черн)'!A:D,4,0) -> 52
A99: Мўйноқ | C99: 26 | D99: 61 | E99: =+VLOOKUP(A99,'q_1 district (черн)'!A:D,2,0) -> 1 | F99: =+VLOOKUP(A99,'q_1 district (черн)'!A:D,3,0) -> 35 | G99: =+VLOOKUP(A99,'q_1 district (черн)'!A:D,4,0) -> 54
A100: Навбаҳор | B100: 2 | C100: 16 | D100: 59 | E100: =+VLOOKUP(A100,'q_1 district (черн)'!A:D,2,0) -> 7 | F100: =+VLOOKUP(A100,'q_1 district (черн)'!A:D,3,0) -> 21 | G100: =+VLOOKUP(A100,'q_1 district (черн)'!A:D,4,0) -> 50
A101: Навоий ш. | B101: 12 | C101: 20 | D101: 48 | E101: =+VLOOKUP(A101,'q_1 district (черн)'!A:D,2,0) -> 9 | F101: =+VLOOKUP(A101,'q_1 district (черн)'!A:D,3,0) -> 24 | G101: =+VLOOKUP(A101,'q_1 district (черн)'!A:D,4,0) -> 39
A102: Наманган | B102: 5 | C102: 10 | D102: 59 | E102: =+VLOOKUP(A102,'q_1 district (черн)'!A:D,2,0) -> 5 | F102: =+VLOOKUP(A102,'q_1 district (черн)'!A:D,3,0) -> 7 | G102: =+VLOOKUP(A102,'q_1 district (черн)'!A:D,4,0) -> 71
A103: Наманган ш. | B103: 10 | C103: 13 | D103: 58 | E103: =+VLOOKUP(A103,'q_1 district (черн)'!A:D,2,0) -> 12 | F103: =+VLOOKUP(A103,'q_1 district (черн)'!A:D,3,0) -> 15 | G103: =+VLOOKUP(A103,'q_1 district (черн)'!A:D,4,0) -> 62
A104: Нарпай | B104: 9 | C104: 20 | D104: 56 | E104: =+VLOOKUP(A104,'q_1 district (черн)'!A:D,2,0) -> 7 | F104: =+VLOOKUP(A104,'q_1 district (черн)'!A:D,3,0) -> 22 | G104: =+VLOOKUP(A104,'q_1 district (черн)'!A:D,4,0) -> 49
A105: Нишон | B105: 9 | C105: 15 | D105: 55 | E105: =+VLOOKUP(A105,'q_1 district (черн)'!A:D,2,0) -> 7 | F105: =+VLOOKUP(A105,'q_1 district (черн)'!A:D,3,0) -> 22 | G105: =+VLOOKUP(A105,'q_1 district (черн)'!A:D,4,0) -> 48
A106: Норин | B106: 13 | C106: 15 | D106: 57 | E106: =+VLOOKUP(A106,'q_1 district (черн)'!A:D,2,0) -> 10 | F106: =+VLOOKUP(A106,'q_1 district (черн)'!A:D,3,0) -> 24 | G106: =+VLOOKUP(A106,'q_1 district (черн)'!A:D,4,0) -> 57
A107: Нукус | B107: 1 | C107: 24 | D107: 49 | E107: =+VLOOKUP(A107,'q_1 district (черн)'!A:D,2,0) -> 4 | F107: =+VLOOKUP(A107,'q_1 district (черн)'!A:D,3,0) -> 20 | G107: =+VLOOKUP(A107,'q_1 district (черн)'!A:D,4,0) -> 49
A108: Нукус ш. | B108: 8 | C108: 20 | D108: 56 | E108: =+VLOOKUP(A108,'q_1 district (черн)'!A:D,2,0) -> 7 | F108: =+VLOOKUP(A108,'q_1 district (черн)'!A:D,3,0) -> 27 | G108: =+VLOOKUP(A108,'q_1 district (черн)'!A:D,4,0) -> 46
A109: Нурафшон ш. | B109: 16 | C109: 24 | D109: 41 | E109: =+VLOOKUP(A109,'q_1 district (черн)'!A:D,2,0) -> 22 | F109: =+VLOOKUP(A109,'q_1 district (черн)'!A:D,3,0) -> 24 | G109: =+VLOOKUP(A109,'q_1 district (черн)'!A:D,4,0) -> 48
A110: Нуробод | B110: 6 | C110: 15 | D110: 57 | E110: =+VLOOKUP(A110,'q_1 district (черн)'!A:D,2,0) -> 6 | F110: =+VLOOKUP(A110,'q_1 district (черн)'!A:D,3,0) -> 19 | G110: =+VLOOKUP(A110,'q_1 district (черн)'!A:D,4,0) -> 58
A111: Нурота | B111: 9 | C111: 18 | D111: 51 | E111: =+VLOOKUP(A111,'q_1 district (черн)'!A:D,2,0) -> 9 | F111: =+VLOOKUP(A111,'q_1 district (черн)'!A:D,3,0) -> 25 | G111: =+VLOOKUP(A111,'q_1 district (черн)'!A:D,4,0) -> 60
... A146: Тойлоқ | B146: 4 | C146: 12 | D146: 56 | E146: =+VLOOKUP(A146,'q_1 district (черн)'!A:D,2,0) -> 7 | F146: =+VLOOKUP(A146,'q_1 district (черн)'!A:D,3,0) -> 6 | G146: =+VLOOKUP(A146,'q_1 district (черн)'!A:D,4,0) -> 66
A147: Томди | C147: 6 | D147: 78 | E147: =+VLOOKUP(A147,'q_1 district (черн)'!A:D,2,0) -> 0 | F147: =+VLOOKUP(A147,'q_1 district (черн)'!A:D,3,0) -> 25 | G147: =+VLOOKUP(A147,'q_1 district (черн)'!A:D,4,0) -> 69
A148: Тошкент | B148: 15 | C148: 24 | D148: 41 | E148: =+VLOOKUP(A148,'q_1 district (черн)'!A:D,2,0) -> 16 | F148: =+VLOOKUP(A148,'q_1 district (черн)'!A:D,3,0) -> 20 | G148: =+VLOOKUP(A148,'q_1 district (черн)'!A:D,4,0) -> 40
A149: Тошлоқ | B149: 7 | C149: 10 | D149: 57 | E149: =+VLOOKUP(A149,'q_1 district (черн)'!A:D,2,0) -> 12 | F149: =+VLOOKUP(A149,'q_1 district (черн)'!A:D,3,0) -> 16 | G149: =+VLOOKUP(A149,'q_1 district (черн)'!A:D,4,0) -> 57
A150: Тупроққальа | B150: 11 | C150: 12 | D150: 65 | E150: =+VLOOKUP(A150,'q_1 district (черн)'!A:D,2,0) -> 12 | F150: =+VLOOKUP(A150,'q_1 district (черн)'!A:D,3,0) -> 32 | G150: =+VLOOKUP(A150,'q_1 district (черн)'!A:D,4,0) -> 37
A151: Тўрақўрғон | B151: 4 | C151: 11 | D151: 72 | E151: =+VLOOKUP(A151,'q_1 district (черн)'!A:D,2,0) -> 4 | F151: =+VLOOKUP(A151,'q_1 district (черн)'!A:D,3,0) -> 13 | G151: =+VLOOKUP(A151,'q_1 district (черн)'!A:D,4,0) -> 60
A152: Тўрткўл | B152: 11 | C152: 15 | D152: 58 | E152: =+VLOOKUP(A152,'q_1 district (черн)'!A:D,2,0) -> 7 | F152: =+VLOOKUP(A152,'q_1 district (черн)'!A:D,3,0) -> 18 | G152: =+VLOOKUP(A152,'q_1 district (черн)'!A:D,4,0) -> 53
A153: Ўзбекистон | B153: 5 | C153: 13 | D153: 68 | E153: =+VLOOKUP(A153,'q_1 district (черн)'!A:D,2,0) -> 11 | F153: =+VLOOKUP(A153,'q_1 district (черн)'!A:D,3,0) -> 18 | G153: =+VLOOKUP(A153,'q_1 district (черн)'!A:D,4,0) -> 53
A154: Узун | B154: 7 | C154: 11 | D154: 53 | E154: =+VLOOKUP(A154,'q_1 district (черн)'!A:D,2,0) -> 5 | F154: =+VLOOKUP(A154,'q_1 district (черн)'!A:D,3,0) -> 9 | G154: =+VLOOKUP(A154,'q_1 district (черн)'!A:D,4,0) -> 59
A155: Уйчи | B155: 6 | C155: 15 | D155: 65 | E155: =+VLOOKUP(A155,'q_1 district (черн)'!A:D,2,0) -> 8 | F155: =+VLOOKUP(A155,'q_1 district (черн)'!A:D,3,0) -> 19 | G155: =+VLOOKUP(A155,'q_1 district (черн)'!A:D,4,0) -> 54
A156: Улуғнор | B156: 13 | C156: 15 | D156: 55 | E156: =+VLOOKUP(A156,'q_1 district (черн)'!A:D,2,0) -> 14 | F156: =+VLOOKUP(A156,'q_1 district (черн)'!A:D,3,0) -> 26 | G156: =+VLOOKUP(A156,'q_1 district (черн)'!A:D,4,0) -> 46
A157: Урганч | B157: 12 | C157: 21 | D157: 52 | E157: =+VLOOKUP(A157,'q_1 district (черн)'!A:D,2,0) -> 10 | F157: =+VLOOKUP(A157,'q_1 district (черн)'!A:D,3,0) -> 20 | G157: =+VLOOKUP(A157,'q_1 district (черн)'!A:D,4,0) -> 53
...

Sheet q_1 district (черн)
B1: Август
A2: district | B2: Ёмонлашади | C2: Ўзгармайди | D2: Яхшиланади
A3: Ёзёвон | B3: 6 | C3: 12 | D3: 61
A4: Ўзбекистон | B4: 11 | C4: 18 | D4: 53
A5: Ўртачирчиқ | B5: 10 | C5: 19 | D5: 60
A6: Амударё | B6: 4 | C6: 18 | D6: 52
A7: Ангор | B7: 9 | C7: 14 | D7: 56
A8: Ангрен ш. | B8: 8 | C8: 28 | D8: 48
A9: Андижон | B9: 6 | C9: 17 | D9: 51
A10: Андижон ш. | B10: 10 | C10: 12 | D10: 53
A11: Арнасой | B11: 10 | C11: 20 | D11: 57
A12: Асака | B12: 8 | C12: 19 | D12: 50
A13: Балиқчи | B13: 6 | C13: 16 | D13: 61
A14: Бандихон | B14: 11 | C14: 13 | D14: 56
... A123: Тойлоқ | B123: 7 | C123: 6 | D123: 66
A124: Томди | C124: 25 | D124: 69
A125: Тошкент | B125: 16 | C125: 20 | D125: 40
A126: Тошлоқ | B126: 12 | C126: 16 | D126: 57
A127: Тупроққальа | B127: 12 | C127: 32 | D127: 37
A128: Тўрақўрғон | B128: 4 | C128: 13 | D128: 60
A129: Тўрткўл | B129: 7 | C129: 18 | D129: 53
A130: Узун | B130: 5 | C130: 9 | D130: 59
A131: Уйчи | B131: 8 | C131: 19 | D131: 54
A132: Улуғнор | B132: 14 | C132: 26 | D132: 46
A133: Урганч | B133: 10 | C133: 20 | D133: 53
A134: Урганч ш. | B134: 13 | C134: 27 | D134: 45
A135: Ургут | B135: 4 | C135: 8 | D135: 68
A136: Учкўприк | B136: 6 | C136: 11 | D136: 59
... A168: Шофиркон | B168: 7 | C168: 17 | D168: 61
A169: Шуманай | C169: 22 | D169: 58
A170: Шўрчи | B170: 14 | C170: 9 | D170: 52
A171: Элликқалъа | B171: 11 | C171: 15 | D171: 50
A172: Юнусобод | B172: 7 | C172: 26 | D172: 52
A173: Юқоричирчиқ | B173: 9 | C173: 19 | D173: 44
A174: Яккабоғ | B174: 8 | C174: 26 | D174: 45
A175: Яккасарой | B175: 23 | C175: 16 | D175: 48
A176: Янгиариқ | B176: 8 | C176: 21 | D176: 62
A177: Янгибозор | B177: 17 | C177: 21 | D177: 45
A178: Янгиер ш. | B178: 2 | C178: 12 | D178: 63
A179: Янгийўл | B179: 6 | C179: 17 | D179: 53
...

Sheet q_3
B3: 2025 йил май | E3: 2025 йил август
A4: district | B4: Қисқаради | C4: Ўзгармайди | D4: Кўпаяди | E4: Қисқаради | F4: Ўзгармайди | G4: Кўпаяди
A5: Кашкадарё вилояти | B5: 8 | C5: 28 | D5: 41 | E5: =+VLOOKUP(A5,'q_3 (черн)'!A:D,2,0) -> 13 | F5: =+VLOOKUP(A5,'q_3 (черн)'!A:D,3,0) -> 27 | G5: =+VLOOKUP(A5,'q_3 (черн)'!A:D,4,0) -> 41
A6: Тошкент шахри | B6: 9 | C6: 25 | D6: 49 | E6: =+VLOOKUP(A6,'q_3 (черн)'!A:D,2,0) -> 8 | F6: =+VLOOKUP(A6,'q_3 (черн)'!A:D,3,0) -> 27 | G6: =+VLOOKUP(A6,'q_3 (черн)'!A:D,4,0) -> 49
A7: Андижон вилояти | B7: 7 | C7: 23 | D7: 52 | E7: =+VLOOKUP(A7,'q_3 (черн)'!A:D,2,0) -> 15 | F7: =+VLOOKUP(A7,'q_3 (черн)'!A:D,3,0) -> 24 | G7: =+VLOOKUP(A7,'q_3 (черн)'!A:D,4,0) -> 43
A8: Хоразм вилояти | B8: 9 | C8: 22 | D8: 50 | E8: =+VLOOKUP(A8,'q_3 (черн)'!A:D,2,0) -> 13 | F8: =+VLOOKUP(A8,'q_3 (черн)'!A:D,3,0) -> 26 | G8: =+VLOOKUP(A8,'q_3 (черн)'!A:D,4,0) -> 44
A9: Самарканд вилояти | B9: 8 | C9: 22 | D9: 50 | E9: =+VLOOKUP(A9,'q_3 (черн)'!A:D,2,0) -> 16 | F9: =+VLOOKUP(A9,'q_3 (черн)'!A:D,3,0) -> 23 | G9: =+VLOOKUP(A9,'q_3 (черн)'!A:D,4,0) -> 44
A10: Наманган вилояти | B10: 7 | C10: 23 | D10: 53 | E10: =+VLOOKUP(A10,'q_3 (черн)'!A:D,2,0) -> 14 | F10: =+VLOOKUP(A10,'q_3 (черн)'!A:D,3,0) -> 23 | G10: =+VLOOKUP(A10,'q_3 (черн)'!A:D,4,0) -> 49
A11: Фаргона вилояти | B11: 10 | C11: 23 | D11: 49 | E11: =+VLOOKUP(A11,'q_3 (черн)'!A:D,2,0) -> 17 | F11: =+VLOOKUP(A11,'q_3 (черн)'!A:D,3,0) -> 23 | G11: =+VLOOKUP(A11,'q_3 (черн)'!A:D,4,0) -> 45
A12: Бухоро вилояти | B12: 10 | C12: 29 | D12: 44 | E12: =+VLOOKUP(A12,'q_3 (черн)'!A:D,2,0) -> 10 | F12: =+VLOOKUP(A12,'q_3 (черн)'!A:D,3,0) -> 28 | G12: =+VLOOKUP(A12,'q_3 (черн)'!A:D,4,0) -> 45
A13: Коракалпокистон Республикаси | B13: 8 | C13: 27 | D13: 48 | E13: =+VLOOKUP(A13,'q_3 (черн)'!A:D,2,0) -> 15 | F13: =+VLOOKUP(A13,'q_3 (черн)'!A:D,3,0) -> 32 | G13: =+VLOOKUP(A13,'q_3 (черн)'!A:D,4,0) -> 35
A14: Тошкент вилояти | B14: 10 | C14: 28 | D14: 41 | E14: =+VLOOKUP(A14,'q_3 (черн)'!A:D,2,0) -> 14 | F14: =+VLOOKUP(A14,'q_3 (черн)'!A:D,3,0) -> 27 | G14: =+VLOOKUP(A14,'q_3 (черн)'!A:D,4,0) -> 38
A15: Жиззах вилояти | B15: 9 | C15: 23 | D15: 51 | E15: =+VLOOKUP(A15,'q_3 (черн)'!A:D,2,0) -> 13 | F15: =+VLOOKUP(A15,'q_3 (черн)'!A:D,3,0) -> 27 | G15: =+VLOOKUP(A15,'q_3 (черн)'!A:D,4,0) -> 46
A16: Сирдарё вилояти | B16: 10 | C16: 24 | D16: 46 | E16: =+VLOOKUP(A16,'q_3 (черн)'!A:D,2,0) -> 13 | F16: =+VLOOKUP(A16,'q_3 (черн)'!A:D,3,0) -> 28 | G16: =+VLOOKUP(A16,'q_3 (черн)'!A:D,4,0) -> 36
... A19: Республика бўйича ўртача | B19: 9 | C19: 25 | D19: 47 | E19: =+VLOOKUP(A19,'q_3 (черн)'!A:D,2,0) -> 14 | F19: =+VLOOKUP(A19,'q_3 (черн)'!A:D,3,0) -> 26 | G19: =+VLOOKUP(A19,'q_3 (черн)'!A:D,4,0) -> 43

Sheet q_3 (черн)
B1: Август
A2: district | B2: Қисқаради | C2: Ўзгармайди | D2: Кўпаяди
A3: Андижон вилояти | B3: 15 | C3: 24 | D3: 43
A4: Бухоро вилояти | B4: 10 | C4: 28 | D4: 45
A5: Жиззах вилояти | B5: 13 | C5: 27 | D5: 46
A6: Кашкадарё вилояти | B6: 13 | C6: 27 | D6: 41
A7: Коракалпокистон Республикаси | B7: 15 | C7: 32 | D7: 35
A8: Навоий вилояти | B8: 13 | C8: 30 | D8: 44
A9: Наманган вилояти | B9: 14 | C9: 23 | D9: 49
A10: Самарканд вилояти | B10: 16 | C10: 23 | D10: 44
A11: Сирдарё вилояти | B11: 13 | C11: 28 | D11: 36
A12: Сурхандарё вилояти | B12: 12 | C12: 25 | D12: 42
A13: Тошкент вилояти | B13: 14 | C13: 27 | D13: 38
A14: Тошкент шахри | B14: 8 | C14: 27 | D14: 49
... A17: Республика бўйича ўртача | B17: 14 | C17: 26 | D17: 43

Sheet q_3 district
B3: 2025 йил май | E3: 2025 йил август
A4: district | B4: Қисқаради | C4: Ўзгармайди | D4: Кўпаяди | E4: Қисқаради | F4: Ўзгармайди | G4: Кўпаяди
A5: Амударё | B5: 16 | C5: 34 | D5: 35 | E5: =+VLOOKUP(A5,'q_3 district (черн)'!A:D,2,0) -> 21 | F5: =+VLOOKUP(A5,'q_3 district (черн)'!A:D,3,0) -> 29 | G5: =+VLOOKUP(A5,'q_3 district (черн)'!A:D,4,0) -> 31
A6: Ангор | B6: 12 | C6: 15 | D6: 51 | E6: =+VLOOKUP(A6,'q_3 district (черн)'!A:D,2,0) -> 12 | F6: =+VLOOKUP(A6,'q_3 district (черн)'!A:D,3,0) -> 25 | G6: =+VLOOKUP(A6,'q_3 district (черн)'!A:D,4,0) -> 44
A7: Ангрен ш. | B7: 12 | C7: 33 | D7: 33 | E7: =+VLOOKUP(A7,'q_3 district (черн)'!A:D,2,0) -> 10 | F7: =+VLOOKUP(A7,'q_3 district (черн)'!A:D,3,0) -> 27 | G7: =+VLOOKUP(A7,'q_3 district (черн)'!A:D,4,0) -> 40
A8: Андижон | B8: 7 | C8: 24 | D8: 52 | E8: =+VLOOKUP(A8,'q_3 district (черн)'!A:D,2,0) -> 12 | F8: =+VLOOKUP(A8,'q_3 district (черн)'!A:D,3,0) -> 16 | G8: =+VLOOKUP(A8,'q_3 district (черн)'!A:D,4,0) -> 55
A9: Андижон ш. | B9: 6 | C9: 21 | D9: 48 | E9: =+VLOOKUP(A9,'q_3 district (черн)'!A:D,2,0) -> 14 | F9: =+VLOOKUP(A9,'q_3 district (черн)'!A:D,3,0) -> 26 | G9: =+VLOOKUP(A9,'q_3 district (черн)'!A:D,4,0) -> 44
A10: Арнасой | B10: 13 | C10: 18 | D10: 51 | E10: =+VLOOKUP(A10,'q_3 district (черн)'!A:D,2,0) -> 11 | F10: =+VLOOKUP(A10,'q_3 district (черн)'!A:D,3,0) -> 36 | G10: =+VLOOKUP(A10,'q_3 district (черн)'!A:D,4,0) -> 40
A11: Асака | B11: 7 | C11: 25 | D11: 47 | E11: =+VLOOKUP(A11,'q_3 district (черн)'!A:D,2,0) -> 16 | F11: =+VLOOKUP(A11,'q_3 district (черн)'!A:D,3,0) -> 25 | G11: =+VLOOKUP(A11,'q_3 district (черн)'!A:D,4,0) -> 37
A12: Балиқчи | B12: 10 | C12: 18 | D12: 48 | E12: =+VLOOKUP(A12,'q_3 district (черн)'!A:D,2,0) -> 16 | F12: =+VLOOKUP(A12,'q_3 district (черн)'!A:D,3,0) -> 16 | G12: =+VLOOKUP(A12,'q_3 district (черн)'!A:D,4,0) -> 47
A13: Бандихон | B13: 4 | C13: 36 | D13: 44 | E13: =+VLOOKUP(A13,'q_3 district (черн)'!A:D,2,0) -> 10 | F13: =+VLOOKUP(A13,'q_3 district (черн)'!A:D,3,0) -> 23 | G13: =+VLOOKUP(A13,'q_3 district (черн)'!A:D,4,0) -> 45
A14: Бахмал | B14: 9 | C14: 27 | D14: 47 | E14: =+VLOOKUP(A14,'q_3 district (черн)'!A:D,2,0) -> 6 | F14: =+VLOOKUP(A14,'q_3 district (черн)'!A:D,3,0) -> 26 | G14: =+VLOOKUP(A14,'q_3 district (черн)'!A:D,4,0) -> 59
A15: Бекобод | B15: 8 | C15: 26 | D15: 40 | E15: =+VLOOKUP(A15,'q_3 district (черн)'!A:D,2,0) -> 22 | F15: =+VLOOKUP(A15,'q_3 district (черн)'!A:D,3,0) -> 24 | G15: =+VLOOKUP(A15,'q_3 district (черн)'!A:D,4,0) -> 43
A16: Бекобод ш. | B16: 8 | C16: 34 | D16: 42 | E16: =+VLOOKUP(A16,'q_3 district (черн)'!A:D,2,0) -> 10 | F16: =+VLOOKUP(A16,'q_3 district (черн)'!A:D,3,0) -> 30 | G16: =+VLOOKUP(A16,'q_3 district (черн)'!A:D,4,0) -> 44
... A210: Республика бўйича ўртача | B210: 9 | C210: 25 | D210: 47 | E210: =+VLOOKUP(A210,'q_3 district (черн)'!A:D,2,0) -> 14 | F210: =+VLOOKUP(A210,'q_3 district (черн)'!A:D,3,0) -> 26 | G210: =+VLOOKUP(A210,'q_3 district (черн)'!A:D,4,0) -> 43

Sheet q_3 district (черн)
B1: Август
A2: district | B2: Қисқаради | C2: Ўзгармайди | D2: Кўпаяди
A3: Ёзёвон | B3: 16 | C3: 15 | D3: 50
A4: Ўзбекистон | B4: 22 | C4: 24 | D4: 44
A5: Ўртачирчиқ | B5: 18 | C5: 24 | D5: 50
A6: Амударё | B6: 21 | C6: 29 | D6: 31
A7: Ангор | B7: 12 | C7: 25 | D7: 44
A8: Ангрен ш. | B8: 10 | C8: 27 | D8: 40
A9: Андижон | B9: 12 | C9: 16 | D9: 55
A10: Андижон ш. | B10: 14 | C10: 26 | D10: 44
A11: Арнасой | B11: 11 | C11: 36 | D11: 40
A12: Асака | B12: 16 | C12: 25 | D12: 37
A13: Балиқчи | B13: 16 | C13: 16 | D13: 47
A14: Бандихон | B14: 10 | C14: 23 | D14: 45
... A208: Республика бўйича ўртача | B208: 14 | C208: 26 | D208: 43

Sheet q_5
B3: 2025 йил май | E3: 2025 йил август
A4: district | B4: Камаяди | C4: Ўзгармайди | D4: Кўпаяди | E4: Камаяди | F4: Ўзгармайди | G4: Кўпаяди
A5: Кашкадарё вилояти | B5: 9 | C5: 23 | D5: 40 | E5: =+VLOOKUP(A5,'q_5 (черн)'!A:D,2,0) -> 11 | F5: =+VLOOKUP(A5,'q_5 (черн)'!A:D,3,0) -> 25 | G5: =+VLOOKUP(A5,'q_5 (черн)'!A:D,4,0) -> 37
A6: Тошкент шахри | B6: 10 | C6: 22 | D6: 38 | E6: =+VLOOKUP(A6,'q_5 (черн)'!A:D,2,0) -> 13 | F6: =+VLOOKUP(A6,'q_5 (черн)'!A:D,3,0) -> 25 | G6: =+VLOOKUP(A6,'q_5 (черн)'!A:D,4,0) -> 39
A7: Андижон вилояти | B7: 7 | C7: 21 | D7: 45 | E7: =+VLOOKUP(A7,'q_5 (черн)'!A:D,2,0) -> 16 | F7: =+VLOOKUP(A7,'q_5 (черн)'!A:D,3,0) -> 21 | G7: =+VLOOKUP(A7,'q_5 (черн)'!A:D,4,0) -> 44
A8: Хоразм вилояти | B8: 10 | C8: 23 | D8: 39 | E8: =+VLOOKUP(A8,'q_5 (черн)'!A:D,2,0) -> 12 | F8: =+VLOOKUP(A8,'q_5 (черн)'!A:D,3,0) -> 25 | G8: =+VLOOKUP(A8,'q_5 (черн)'!A:D,4,0) -> 41
A9: Самарканд вилояти | B9: 9 | C9: 20 | D9: 42 | E9: =+VLOOKUP(A9,'q_5 (черн)'!A:D,2,0) -> 16 | F9: =+VLOOKUP(A9,'q_5 (черн)'!A:D,3,0) -> 20 | G9: =+VLOOKUP(A9,'q_5 (черн)'!A:D,4,0) -> 45
A10: Наманган вилояти | B10: 9 | C10: 20 | D10: 45 | E10: =+VLOOKUP(A10,'q_5 (черн)'!A:D,2,0) -> 16 | F10: =+VLOOKUP(A10,'q_5 (черн)'!A:D,3,0) -> 21 | G10: =+VLOOKUP(A10,'q_5 (черн)'!A:D,4,0) -> 46
A11: Фаргона вилояти | B11: 11 | C11: 21 | D11: 42 | E11: =+VLOOKUP(A11,'q_5 (черн)'!A:D,2,0) -> 18 | F11: =+VLOOKUP(A11,'q_5 (черн)'!A:D,3,0) -> 20 | G11: =+VLOOKUP(A11,'q_5 (черн)'!A:D,4,0) -> 41
